Workbook

Sheet 🌐 BLOOMBERG SCREENER v27
A1: BLOOMBERG SCREENER v27
A2: Cap nhat Q2 2026: 29/05/2026 | Composite Score tu dong | BCTC Q1/2026
A4: ⚙️ 8 FACTOR FILTERS — Chỉnh ô VÀNG, kết quả tự cập nhật
A5: STT | B5: A. P/E MAX | C5: B. P/E MIN | D5: C. P/B MAX | E5: D. ROE MIN% | F5: E. Vốn hóa MIN | G5: F. %YTD MIN% | H5: G. Tín hiệu | I5: H. Ngành
A6: → | B6: 25 | C6: 0 | D6: 5 | E6: 12 | F6: 1000 | G6: -30 | H6: MUA
A8: 🎯 Tổng đạt: | D8: 178
A10: #
A11: 1 | B11: VTP | C11: 65200 | D11: 16.5 | E11: 2.2 | F11: 14.5 | G11: 12500 | H11: 32.5 | I11: 90 | J11: =IFERROR(VLOOKUP(B11,'📈 Cổ Phiếu VN 🔍'!$A:$L,9,0),"") | K11: =IFERROR(VLOOKUP(B11,'📈 Cổ Phiếu VN 🔍'!$A:$L,10,0),"") | L11: =IFERROR(VLOOKUP(B11,'📈 Cổ Phiếu VN 🔍'!$A:$L,11,0),"") | M11: =IFERROR(MAX(0,30-F11*1.2)+MIN(30,H11*1.2)+MAX(0,10+K11)*0.5+IF(L11="MUA",25,IF(L11="GIỮ",15,0)),"")
A12: 2 | B12: VSH | C12: 42800 | D12: 10.5 | E12: 1.2 | F12: 12.5 | G12: 3500 | H12: 12.5 | I12: 90 | J12: =IFERROR(VLOOKUP(B12,'📈 Cổ Phiếu VN 🔍'!$A:$L,9,0),"") | K12: =IFERROR(VLOOKUP(B12,'📈 Cổ Phiếu VN 🔍'!$A:$L,10,0),"") | L12: =IFERROR(VLOOKUP(B12,'📈 Cổ Phiếu VN 🔍'!$A:$L,11,0),"") | M12: =IFERROR(MAX(0,30-F12*1.2)+MIN(30,H12*1.2)+MAX(0,10+K12)*0.5+IF(L12="MUA",25,IF(L12="GIỮ",15,0)),"")
A13: 3 | B13: VEA | C13: =IFERROR(INDEX('📡 LIVE PRICE FEED'!$D$4:$D$300,MATCH(A176,'📡 LIVE PRICE FEED'!$A$4:$A$300,0)),58500) | D13: 9.5 | E13: 1.4 | F13: 16.5 | G13: 77000 | H13: 12.5 | I13: 90 | J13: =IFERROR(VLOOKUP(B13,'📈 Cổ Phiếu VN 🔍'!$A:$L,9,0),"") | K13: =IFERROR(VLOOKUP(B13,'📈 Cổ Phiếu VN 🔍'!$A:$L,10,0),"") | L13: =IFERROR(VLOOKUP(B13,'📈 Cổ Phiếu VN 🔍'!$A:$L,11,0),"") | M13: =IFERROR(MAX(0,30-F13*1.2)+MIN(30,H13*1.2)+MAX(0,10+K13)*0.5+IF(L13="MUA",25,IF(L13="GIỮ",15,0)),"")
A14: 4 | B14: VCS | C14: 38400 | D14: 10.5 | E14: 1.5 | F14: 14.5 | G14: 7500 | H14: 8.5 | I14: 90 | J14: =IFERROR(VLOOKUP(B14,'📈 Cổ Phiếu VN 🔍'!$A:$L,9,0),"") | K14: =IFERROR(VLOOKUP(B14,'📈 Cổ Phiếu VN 🔍'!$A:$L,10,0),"") | L14: =IFERROR(VLOOKUP(B14,'📈 Cổ Phiếu VN 🔍'!$A:$L,11,0),"") | M14: =IFERROR(MAX(0,30-F14*1.2)+MIN(30,H14*1.2)+MAX(0,10+K14)*0.5+IF(L14="MUA",25,IF(L14="GIỮ",15,0)),"")
A15: 5 | B15: VCI | C15: 25000 | D15: 13.4 | E15: 2.1 | F15: 16.5 | G15: 15500 | H15: 18.5 | I15: 90 | J15: =IFERROR(VLOOKUP(B15,'📈 Cổ Phiếu VN 🔍'!$A:$L,9,0),"") | K15: =IFERROR(VLOOKUP(B15,'📈 Cổ Phiếu VN 🔍'!$A:$L,10,0),"") | L15: =IFERROR(VLOOKUP(B15,'📈 Cổ Phiếu VN 🔍'!$A:$L,11,0),"") | M15: =IFERROR(MAX(0,30-F15*1.2)+MIN(30,H15*1.2)+MAX(0,10+K15)*0.5+IF(L15="MUA",25,IF(L15="GIỮ",15,0)),"")
A16: 6 | B16: VCF | C16: =IFERROR(INDEX('📡 LIVE PRICE FEED'!$D$4:$D$300,MATCH(A217,'📡 LIVE PRICE FEED'!$A$4:$A$300,0)),195000) | D16: 14.5 | E16: 2.1 | F16: 16.5 | G16: 4200 | H16: 2.5 | I16: 90 | J16: =IFERROR(VLOOKUP(B16,'📈 Cổ Phiếu VN 🔍'!$A:$L,9,0),"") | K16: =IFERROR(VLOOKUP(B16,'📈 Cổ Phiếu VN 🔍'!$A:$L,10,0),"") | L16: =IFERROR(VLOOKUP(B16,'📈 Cổ Phiếu VN 🔍'!$A:$L,11,0),"") | M16: =IFERROR(MAX(0,30-F16*1.2)+MIN(30,H16*1.2)+MAX(0,10+K16)*0.5+IF(L16="MUA",25,IF(L16="GIỮ",15,0)),"")
A17: 7 | B17: TRA | C17: 79000 | D17: 16.5 | E17: 2.5 | F17: 14.5 | G17: 3200 | H17: 15.5 | I17: 90 | J17: =IFERROR(VLOOKUP(B17,'📈 Cổ Phiếu VN 🔍'!$A:$L,9,0),"") | K17: =IFERROR(VLOOKUP(B17,'📈 Cổ Phiếu VN 🔍'!$A:$L,10,0),"") | L17: =IFERROR(VLOOKUP(B17,'📈 Cổ Phiếu VN 🔍'!$A:$L,11,0),"") | M17: =IFERROR(MAX(0,30-F17*1.2)+MIN(30,H17*1.2)+MAX(0,10+K17)*0.5+IF(L17="MUA",25,IF(L17="GIỮ",15,0)),"")
A18: 8 | B18: TNG | C18: 18900 | D18: 10.5 | E18: 1.4 | F18: 14.5 | G18: 2200 | H18: 15.5 | I18: 90 | J18: =IFERROR(VLOOKUP(B18,'📈 Cổ Phiếu VN 🔍'!$A:$L,9,0),"") | K18: =IFERROR(VLOOKUP(B18,'📈 Cổ Phiếu VN 🔍'!$A:$L,10,0),"") | L18: =IFERROR(VLOOKUP(B18,'📈 Cổ Phiếu VN 🔍'!$A:$L,11,0),"") | M18: =IFERROR(MAX(0,30-F18*1.2)+MIN(30,H18*1.2)+MAX(0,10+K18)*0.5+IF(L18="MUA",25,IF(L18="GIỮ",15,0)),"")
A19: 9 | B19: TBC | C19: 31850 | D19: 11.5 | E19: 1.3 | F19: 12.5 | G19: 2800 | H19: 15.5 | I19: 90 | J19: =IFERROR(VLOOKUP(B19,'📈 Cổ Phiếu VN 🔍'!$A:$L,9,0),"") | K19: =IFERROR(VLOOKUP(B19,'📈 Cổ Phiếu VN 🔍'!$A:$L,10,0),"") | L19: =IFERROR(VLOOKUP(B19,'📈 Cổ Phiếu VN 🔍'!$A:$L,11,0),"") | M19: =IFERROR(MAX(0,30-F19*1.2)+MIN(30,H19*1.2)+MAX(0,10+K19)*0.5+IF(L19="MUA",25,IF(L19="GIỮ",15,0)),"")
A20: 10 | B20: SZC | C20: 24700 | D20: 14.7 | E20: 2.4 | F20: 16.5 | G20: 2800 | H20: 8.5 | I20: 90 | J20: =IFERROR(VLOOKUP(B20,'📈 Cổ Phiếu VN 🔍'!$A:$L,9,0),"") | K20: =IFERROR(VLOOKUP(B20,'📈 Cổ Phiếu VN 🔍'!$A:$L,10,0),"") | L20: =IFERROR(VLOOKUP(B20,'📈 Cổ Phiếu VN 🔍'!$A:$L,11,0),"") | M20: =IFERROR(MAX(0,30-F20*1.2)+MIN(30,H20*1.2)+MAX(0,10+K20)*0.5+IF(L20="MUA",25,IF(L20="GIỮ",15,0)),"")
A21: 11 | B21: SSI | C21: 27550 | D21: 14.5 | E21: 1.8 | F21: 12.5 | G21: 42000 | H21: 8.5 | I21: 90 | J21: =IFERROR(VLOOKUP(B21,'📈 Cổ Phiếu VN 🔍'!$A:$L,9,0),"") | K21: =IFERROR(VLOOKUP(B21,'📈 Cổ Phiếu VN 🔍'!$A:$L,10,0),"") | L21: =IFERROR(VLOOKUP(B21,'📈 Cổ Phiếu VN 🔍'!$A:$L,11,0),"") | M21: =IFERROR(MAX(0,30-F21*1.2)+MIN(30,H21*1.2)+MAX(0,10+K21)*0.5+IF(L21="MUA",25,IF(L21="GIỮ",15,0)),"")
A22: 12 | B22: SLS | C22: =IFERROR(INDEX('📡 LIVE PRICE FEED'!$D$4:$D$300,MATCH(A163,'📡 LIVE PRICE FEED'!$A$4:$A$300,0)),158000) | D22: 12.4 | E22: 1.5 | F22: 13.5 | G22: 1800 | H22: 55.5 | I22: 90 | J22: =IFERROR(VLOOKUP(B22,'📈 Cổ Phiếu VN 🔍'!$A:$L,9,0),"") | K22: =IFERROR(VLOOKUP(B22,'📈 Cổ Phiếu VN 🔍'!$A:$L,10,0),"") | L22: =IFERROR(VLOOKUP(B22,'📈 Cổ Phiếu VN 🔍'!$A:$L,11,0),"") | M22: =IFERROR(MAX(0,30-F22*1.2)+MIN(30,H22*1.2)+MAX(0,10+K22)*0.5+IF(L22="MUA",25,IF(L22="GIỮ",15,0)),"")
A23: 13 | B23: SIP | C23: 52000 | D23: 13.5 | E23: 2.2 | F23: 17.8 | G23: 5500 | H23: 22.5 | I23: 90 | J23: =IFERROR(VLOOKUP(B23,'📈 Cổ Phiếu VN 🔍'!$A:$L,9,0),"") | K23: =IFERROR(VLOOKUP(B23,'📈 Cổ Phiếu VN 🔍'!$A:$L,10,0),"") | L23: =IFERROR(VLOOKUP(B23,'📈 Cổ Phiếu VN 🔍'!$A:$L,11,0),"") | M23: =IFERROR(MAX(0,30-F23*1.2)+MIN(30,H23*1.2)+MAX(0,10+K23)*0.5+IF(L23="MUA",25,IF(L23="GIỮ",15,0)),"")
A24: 14 | B24: SGN | C24: 51900 | D24: 12.4 | E24: 2.5 | F24: 22.5 | G24: 3800 | H24: 12.5 | I24: 90 | J24: =IFERROR(VLOOKUP(B24,'📈 Cổ Phiếu VN 🔍'!$A:$L,9,0),"") | K24: =IFERROR(VLOOKUP(B24,'📈 Cổ Phiếu VN 🔍'!$A:$L,10,0),"") | L24: =IFERROR(VLOOKUP(B24,'📈 Cổ Phiếu VN 🔍'!$A:$L,11,0),"") | M24: =IFERROR(MAX(0,30-F24*1.2)+MIN(30,H24*1.2)+MAX(0,10+K24)*0.5+IF(L24="MUA",25,IF(L24="GIỮ",15,0)),"")
A25: 15 | B25: SCS | C25: 51600 | D25: 15.4 | E25: 3.2 | F25: 22.5 | G25: 4500 | H25: 18.5 | I25: 90 | J25: =IFERROR(VLOOKUP(B25,'📈 Cổ Phiếu VN 🔍'!$A:$L,9,0),"") | K25: =IFERROR(VLOOKUP(B25,'📈 Cổ Phiếu VN 🔍'!$A:$L,10,0),"") | L25: =IFERROR(VLOOKUP(B25,'📈 Cổ Phiếu VN 🔍'!$A:$L,11,0),"") | M25: =IFERROR(MAX(0,30-F25*1.2)+MIN(30,H25*1.2)+MAX(0,10+K25)*0.5+IF(L25="MUA",25,IF(L25="GIỮ",15,0)),"")
A26: 16 | B26: QNS | C26: =IFERROR(INDEX('📡 LIVE PRICE FEED'!$D$4:$D$300,MATCH(A240,'📡 LIVE PRICE FEED'!$A$4:$A$300,0)),38000) | D26: 10.5 | E26: 1.8 | F26: 18.5 | G26: 12500 | H26: 8.5 | I26: 90 | J26: =IFERROR(VLOOKUP(B26,'📈 Cổ Phiếu VN 🔍'!$A:$L,9,0),"") | K26: =IFERROR(VLOOKUP(B26,'📈 Cổ Phiếu VN 🔍'!$A:$L,10,0),"") | L26: =IFERROR(VLOOKUP(B26,'📈 Cổ Phiếu VN 🔍'!$A:$L,11,0),"") | M26: =IFERROR(MAX(0,30-F26*1.2)+MIN(30,H26*1.2)+MAX(0,10+K26)*0.5+IF(L26="MUA",25,IF(L26="GIỮ",15,0)),"")
A27: 17 | B27: PVT | C27: 21900 | D27: 11.6 | E27: 1.4 | F27: 12.7 | G27: 8500 | H27: 18.5 | I27: 90 | J27: =IFERROR(VLOOKUP(B27,'📈 Cổ Phiếu VN 🔍'!$A:$L,9,0),"") | K27: =IFERROR(VLOOKUP(B27,'📈 Cổ Phiếu VN 🔍'!$A:$L,10,0),"") | L27: =IFERROR(VLOOKUP(B27,'📈 Cổ Phiếu VN 🔍'!$A:$L,11,0),"") | M27: =IFERROR(MAX(0,30-F27*1.2)+MIN(30,H27*1.2)+MAX(0,10+K27)*0.5+IF(L27="MUA",25,IF(L27="GIỮ",15,0)),"")
A28: 18 | B28: PPC | C28: 9830 | D28: 8.2 | E28: 1.05 | F28: 12.8 | G28: 5500 | H28: 5.5 | I28: 90 | J28: =IFERROR(VLOOKUP(B28,'📈 Cổ Phiếu VN 🔍'!$A:$L,9,0),"") | K28: =IFERROR(VLOOKUP(B28,'📈 Cổ Phiếu VN 🔍'!$A:$L,10,0),"") | L28: =IFERROR(VLOOKUP(B28,'📈 Cổ Phiếu VN 🔍'!$A:$L,11,0),"") | M28: =IFERROR(MAX(0,30-F28*1.2)+MIN(30,H28*1.2)+MAX(0,10+K28)*0.5+IF(L28="MUA",25,IF(L28="GIỮ",15,0)),"")
A29: 19 | B29: PLX | C29: 39450 | D29: 17.5 | E29: 2.1 | F29: 12.5 | G29: 68000 | H29: -5.5 | I29: 90 | J29: =IFERROR(VLOOKUP(B29,'📈 Cổ Phiếu VN 🔍'!$A:$L,9,0),"") | K29: =IFERROR(VLOOKUP(B29,'📈 Cổ Phiếu VN 🔍'!$A:$L,10,0),"") | L29: =IFERROR(VLOOKUP(B29,'📈 Cổ Phiếu VN 🔍'!$A:$L,11,0),"") | M29: =IFERROR(MAX(0,30-F29*1.2)+MIN(30,H29*1.2)+MAX(0,10+K29)*0.5+IF(L29="MUA",25,IF(L29="GIỮ",15,0)),"")
A30: 20 | B30: PHR | C30: 67000 | D30: 13.5 | E30: 1.7 | F30: 12.5 | G30: 7800 | H30: 22.5 | I30: 90 | J30: =IFERROR(VLOOKUP(B30,'📈 Cổ Phiếu VN 🔍'!$A:$L,9,0),"") | K30: =IFERROR(VLOOKUP(B30,'📈 Cổ Phiếu VN 🔍'!$A:$L,10,0),"") | L30: =IFERROR(VLOOKUP(B30,'📈 Cổ Phiếu VN 🔍'!$A:$L,11,0),"") | M30: =IFERROR(MAX(0,30-F30*1.2)+MIN(30,H30*1.2)+MAX(0,10+K30)*0.5+IF(L30="MUA",25,IF(L30="GIỮ",15,0)),"")
A31: 20
A33: 🎯 6 PRESET CHIẾN LƯỢC — Tham khảo ngưỡng (copy vô ô vàng B6:I6)
A34: Preset | B34: P/E max | C34: P/E min | D34: P/B max | E34: ROE min | F34: Vốn hóa min | G34: %YTD min | H34: Tín hiệu | I34: Ý nghĩa
A35: Buffett Value | B35: 15 | C35: 5 | D35: 3 | E35: 15 | F35: 5000 | G35: -20 | H35: MUA | I35: Cổ phiếu giá trị: rẻ + ROE cao + vốn hóa lớn
A36: Lynch Growth | B36: 30 | C36: 10 | D36: 5 | E36: 20 | F36: 1000 | G36: 0 | H36: MUA | I36: Tăng trưởng: PE/Growth thấp + ROE cao
A37: Greenblatt Magic | B37: 20 | C37: 5 | D37: 4 | E37: 20 | F37: 2000 | G37: -30 | H37: MUA | I37: Magic Formula: EBIT/EV + ROIC
A38: Defensive | B38: 20 | C38: 8 | D38: 2 | E38: 12 | F38: 10000 | G38: -10 | H38: GIỮ | I38: Phòng thủ: blue chip + P/B thấp + vốn lớn
A39: Momentum | B39: 25 | C39: 0 | D39: 5 | E39: 10 | F39: 1000 | G39: 15 | H39: MUA | I39: Xu hướng: %YTD cao + tín hiệu MUA
A40: Deep Value | B40: 10 | C40: 3 | D40: 1.5 | E40: 8 | F40: 500 | G40: -50 | I40: Giá trị sâu: cực rẻ, có thể bị bán quá tay

Sheet 🎯 SÓI v42 — TRA CỨU & DEEP DIV
A1: 🐺 SÓI v42 — TRA CỨU MÃ + DEEP DIVE 31 PHẦN (Hợp nhất SÓI CÔ ĐỘC DANH ĐẠT vào)
A2: ? LIVE 29/05/2026 | Q2 2026 | BCTC Q1/2026 | 213 ma co so THAT
A3: 🐺 SÓI CÔ ĐỘC DANH ĐẠT — Triết lý: "Sói cô độc không cần bầy đàn, chỉ cần kỷ luật, dữ liệu thật và đầu lạnh."
B4: 🔍 NHẬP MÃ → | C4: MBB | E4: Ví dụ: FPT, AAPL, KO, TPCP 5 năm, Vàng SJC miếng, Dragon Capital
A6: 🐺 SÓI CÔ ĐỘC DANH ĐẠT — COMMAND CENTER (Embedded · v42)
A7: ⚡ Master Command Center · 14 module institutional cấp Bridgewater · Citadel · BlackRock · Renaissance — Tự lookup theo mã ở ô C4 phía trên
A9: 📊 TÓM TẮT NHANH MÃ — Tự cập nhật theo ô C4 ở trên đầu sheet
A10: Tên đầy đủ: | C10: =IFERROR(VLOOKUP($C$4,'📈 Cổ Phiếu VN 🔍'!$A:$B,2,0),IFERROR(VLOOKUP($C$4,'🌐 Cổ Phiếu TG 🔍'!$A:$B,2,0),"—")) | F10: Ngành/Lĩnh vực: | H10: =IFERROR(VLOOKUP($C$4,'📈 Cổ Phiếu VN 🔍'!$A:$C,3,0),IFERROR(VLOOKUP($C$4,'🌐 Cổ Phiếu TG 🔍'!$A:$C,3,0),"—"))
A11: Giá hiện tại: | C11: =IFERROR(VLOOKUP($C$4,'📈 Cổ Phiếu VN 🔍'!$A:$D,4,0),IFERROR(VLOOKUP($C$4,'🌐 Cổ Phiếu TG 🔍'!$A:$D,4,0),0)) | F11: Vốn hóa (tỷ ₫): | H11: =IFERROR(VLOOKUP($C$4,'📈 Cổ Phiếu VN 🔍'!$A:$H,8,0),IFERROR(VLOOKUP($C$4,'🌐 Cổ Phiếu TG 🔍'!$A:$H,8,0),0))
A12: P/E (TTM): | C12: =IFERROR(VLOOKUP($C$4,'📈 Cổ Phiếu VN 🔍'!$A:$E,5,0),IFERROR(VLOOKUP($C$4,'🌐 Cổ Phiếu TG 🔍'!$A:$E,5,0),0)) | F12: P/B: | H12: =IFERROR(VLOOKUP($C$4,'📈 Cổ Phiếu VN 🔍'!$A:$F,6,0),IFERROR(VLOOKUP($C$4,'🌐 Cổ Phiếu TG 🔍'!$A:$F,6,0),0))
A13: ROE (%): | C13: =IFERROR(VLOOKUP($C$4,'📈 Cổ Phiếu VN 🔍'!$A:$G,7,0),IFERROR(VLOOKUP($C$4,'🌐 Cổ Phiếu TG 🔍'!$A:$G,7,0),0)) | F13: EPS (₫): | H13: =IFERROR(VLOOKUP($C$4,'📈 Cổ Phiếu VN 🔍'!$A:$I,9,0),IFERROR(VLOOKUP($C$4,'🌐 Cổ Phiếu TG 🔍'!$A:$I,9,0),0))
A14: Cổ tức (%): | C14: =IFERROR(VLOOKUP($C$4,'📈 Cổ Phiếu VN 🔍'!$A:$U,21,0),IFERROR(VLOOKUP($C$4,'🌐 Cổ Phiếu TG 🔍'!$A:$U,21,0),0)) | F14: YTD (%): | H14: =IFERROR(VLOOKUP($C$4,'📈 Cổ Phiếu VN 🔍'!$A:$J,10,0),IFERROR(VLOOKUP($C$4,'🌐 Cổ Phiếu TG 🔍'!$A:$J,10,0),0))
A15: Tín hiệu: | C15: =IFERROR(VLOOKUP($C$4,'📈 Cổ Phiếu VN 🔍'!$A:$K,11,0),IFERROR(VLOOKUP($C$4,'🌐 Cổ Phiếu TG 🔍'!$A:$K,11,0),"N/A")) | F15: ROIC (%): | H15: =IFERROR(VLOOKUP($C$4,'📈 Cổ Phiếu VN 🔍'!$A:$S,19,0),IFERROR(VLOOKUP($C$4,'🌐 Cổ Phiếu TG 🔍'!$A:$S,19,0),0))
A17: 🧭 31 MODULE INSTITUTIONAL v42 (14 cũ + 12 mới của các quỹ huyền thoại)
A18: # | B18: Tên Module (click) | D18: Chức năng chính
A19: 1 | B19: 🔍 FORENSIC 198 MÃ | D19: Máy dò gian lận BCTC — Beneish M + Altman Z + Piotroski cho TẤT CẢ 198 mã VN
A20: 2 | B20: 🧮 WACC + BETA AUTO | D20: Mỗi cổ phiếu 1 lãi suất chiết khấu riêng (CAPM) — không xài 12% chung
A21: 3 | B21: 🔀 SENSITIVITY DCF | D21: Bảng 2 chiều WACC × g — xem giá DCF nhạy thế nào khi giả định lệch
A22: 4 | B22: 🎯 SCENARIO 3-CASE | D22: Bull / Base / Bear có trọng số xác suất → Expected Value (EV)
A23: 5 | B23: 🎲 MONTE CARLO + CVaR | D23: 200 lần tung xúc xắc + CVaR 95% — bắt rủi ro đuôi béo. Bấm F9 để quay lại
A24: 6 | B24: 📈 MARKOWITZ FRONTIER | D24: Tối ưu danh mục bằng Solver — chia tỷ trọng max Sharpe Ratio
A25: 7 | B25: 🛡 HEDGING + SLIPPAGE | D25: Phòng hộ VN30F1M + chi phí trượt giá Square-Root Law
A26: 8 | B26: 🌦 MACRO REGIME 4MÙA | D26: Goldilocks · Reflation · Stagflation · Deflation — đang mùa nào cầm gì
A27: 9 | B27: 📊 BRINSON ATTRIBUTION | D27: Bóc tách Alpha — chọn ngành đúng hay chọn mã đúng
A28: 10 | B28: 📐 FAMA-FRENCH 5F | D28: 5 yếu tố MKT · SMB · HML · RMW · CMA — đo Alpha thật
A29: 11 | B29: 💧 LIQUIDITY LCR SHOCK | D29: Test sốc rút 30%/tuần — Fire-sale Cost, mã nào bán sập sàn
A30: 12 | B30: 📉 ATR TRAILING STOP | D30: Chandelier exit Đỉnh − 3×ATR — cắt lỗ động co giãn theo bản tính mã
... A44: 26 | B44: 🏆 SUPER VERDICT 500 (HH) | D44: Tổng kết 31 module = 500 điểm — Quỹ huyền thoại
B45: Tên đầy đủ: | C45: =IFERROR(IFERROR(VLOOKUP($C$4,'📈 Cổ Phiếu VN 🔍'!$A:$B,2,0),""),IFERROR(IFERROR(VLOOKUP($C$4,'🌐 Cổ Phiếu TG 🔍'!$A:$B,2,0),""),""))
B46: Loại tài sản: | C46: =IFERROR(IF(IFERROR(VLOOKUP($C$4,'📈 Cổ Phiếu VN 🔍'!$A:$A,1,0),"")<>"","🟢 Cổ phiếu VN — "&IFERROR(VLOOKUP($C$4,'📈 Cổ Phiếu VN 🔍'!$A:$C,3,0),""),IF(IFERROR(VLOOKUP($C$4,'🌐 Cổ Phiếu TG 🔍'!$A:$A,1,0),"")<>"","🌐 Cổ phiếu TG — "&IFERROR(VLOOKUP($C$4,'🌐 Cổ Phiếu TG 🔍'!$A:$K,11,0),""),IF(IFERROR(VLOOKUP($C$4,'🏛 Quỹ Lớn 🔍'!$A:$A,1,0),"")<>"","🏛 Quỹ/ETF — "&IFERROR(VLOOKUP($C$4,'🏛 Quỹ Lớn 🔍'!$A:$C,3,0),""),IF(IFERROR(VLOOKUP($C$4,'🏦 Trái Phiếu VN 🔍'!$A:$A,1,0),"")<>"","🏦 Trái phiếu VN","❓ Không tìm thấy mã này")))),"❓ Không tìm thấy") | G46: Giá HT: | H46: =IFERROR(IFERROR(VLOOKUP($C$4,'📈 Cổ Phiếu VN 🔍'!$A:$D,4,0),""),IFERROR(IFERROR(VLOOKUP($C$4,'🌐 Cổ Phiếu TG 🔍'!$A:$D,4,0),""),IFERROR(IFERROR(VLOOKUP($C$4,'🏛 Quỹ Lớn 🔍'!$A:$D,4,0),""),""))) | I46: %YTD: | J46: =IFERROR(IFERROR(VLOOKUP($C$4,'📈 Cổ Phiếu VN 🔍'!$A:$J,10,0),""),IFERROR(IFERROR(VLOOKUP($C$4,'🌐 Cổ Phiếu TG 🔍'!$A:$I,9,0),""),""))
B47: Ngành/Sàn: | C47: =IFERROR(IFERROR(VLOOKUP($C$4,'📈 Cổ Phiếu VN 🔍'!$A:$C,3,0),""),IFERROR(IFERROR(VLOOKUP($C$4,'🌐 Cổ Phiếu TG 🔍'!$A:$K,11,0),""),"")) | G47: Tín hiệu: | H47: =IFERROR(IFERROR(VLOOKUP($C$4,'📈 Cổ Phiếu VN 🔍'!$A:$K,11,0),""),IFERROR(IFERROR(VLOOKUP($C$4,'🌐 Cổ Phiếu TG 🔍'!$A:$J,10,0),""),IFERROR(IFERROR(VLOOKUP($C$4,'🏛 Quỹ Lớn 🔍'!$A:$L,12,0),""),"")))
A49: 📐 PHẦN B: VALUATION SUITE — 10 chỉ số định giá chuẩn quỹ lớn
A50: # | B50: Chỉ số | C50: Giá trị | D50: Ngưỡng tốt | E50: Đánh giá | F50: # | G50: Chỉ số | H50: Giá trị | I50: Ngưỡng tốt | J50: Đánh giá
A51: 1 | B51: P/E (TTM) | C51: =IFERROR(IFERROR(VLOOKUP($C$4,'📈 Cổ Phiếu VN 🔍'!$A:$E,5,0),""),IFERROR(IFERROR(VLOOKUP($C$4,'🌐 Cổ Phiếu TG 🔍'!$A:$E,5,0),""),0)) | D51: 8-18 | E51: =IF(IFERROR(IFERROR(VLOOKUP($C$4,'📈 Cổ Phiếu VN 🔍'!$A:$E,5,0),""),IFERROR(IFERROR(VLOOKUP($C$4,'🌐 Cổ Phiếu TG 🔍'!$A:$E,5,0),""),0))=0,"N/A",IF(IFERROR(IFERROR(VLOOKUP($C$4,'📈 Cổ Phiếu VN 🔍'!$A:$E,5,0),""),IFERROR(IFERROR(VLOOKUP($C$4,'🌐 Cổ Phiếu TG 🔍'!$A:$E,5,0),""),0))<8,"🔵 Rẻ",IF(IFERROR(IFERROR(VLOOKUP($C$4,'📈 Cổ Phiếu VN 🔍'!$A:$E,5,0),""),IFERROR(IFERROR(VLOOKUP($C$4,'🌐 Cổ Phiếu TG 🔍'!$A:$E,5,0),""),0))<18,"🟢 Hợp lý",IF(IFERROR(IFERROR(VLOOKUP($C$4,'📈 Cổ Phiếu VN 🔍'!$A:$E,5,0),""),IFERROR(IFERROR(VLOOKUP($C$4,'🌐 Cổ Phiếu TG 🔍'!$A:$E,5,0),""),0))<25,"🟡 Đắt nhẹ","🔴 Quá đắt")))) | F51: 6 | G51: 6.2 | H51: =IFERROR(IFERROR(IFERROR(VLOOKUP($C$4,'📈 Cổ Phiếu VN 🔍'!$A:$H,8,0),""),IFERROR(IFERROR(VLOOKUP($C$4,'🌐 Cổ Phiếu TG 🔍'!$A:$H,8,0),""),0))*10/IFERROR(IFERROR(VLOOKUP($C$4,'📈 Cổ Phiếu VN 🔍'!$A:$Q,17,0),""),0),"N/A") | I51: < 12 | J51: =IFERROR(IF(IFERROR(IFERROR(VLOOKUP($C$4,'📈 Cổ Phiếu VN 🔍'!$A:$H,8,0),""),IFERROR(IFERROR(VLOOKUP($C$4,'🌐 Cổ Phiếu TG 🔍'!$A:$H,8,0),""),0))*10/IFERROR(IFERROR(VLOOKUP($C$4,'📈 Cổ Phiếu VN 🔍'!$A:$Q,17,0),""),0)<12,"🟢 Tham khảo","🟡 Cao"),"N/A")
A52: 2 | B52: Forward P/E | C52: =IFERROR(IFERROR(IFERROR(VLOOKUP($C$4,'📈 Cổ Phiếu VN 🔍'!$A:$E,5,0),""),IFERROR(IFERROR(VLOOKUP($C$4,'🌐 Cổ Phiếu TG 🔍'!$A:$E,5,0),""),0))/(1+MAX(IFERROR(IFERROR(VLOOKUP($C$4,'📈 Cổ Phiếu VN 🔍'!$A:$J,10,0),""),IFERROR(IFERROR(VLOOKUP($C$4,'🌐 Cổ Phiếu TG 🔍'!$A:$I,9,0),""),0)),0.05)),"N/A") | D52: < P/E HT | E52: =IFERROR(IF(IFERROR(IFERROR(VLOOKUP($C$4,'📈 Cổ Phiếu VN 🔍'!$A:$E,5,0),""),IFERROR(IFERROR(VLOOKUP($C$4,'🌐 Cổ Phiếu TG 🔍'!$A:$E,5,0),""),0))/(1+MAX(IFERROR(IFERROR(VLOOKUP($C$4,'📈 Cổ Phiếu VN 🔍'!$A:$J,10,0),""),IFERROR(IFERROR(VLOOKUP($C$4,'🌐 Cổ Phiếu TG 🔍'!$A:$I,9,0),""),0)),0.05))<IFERROR(IFERROR(VLOOKUP($C$4,'📈 Cổ Phiếu VN 🔍'!$A:$E,5,0),""),IFERROR(IFERROR(VLOOKUP($C$4,'🌐 Cổ Phiếu TG 🔍'!$A:$E,5,0),""),0)),"🟢 Tăng trưởng","🟡 Chú ý"),"N/A") | F52: 7 | G52: DCF Fair Value | H52: =IFERROR(IF(IFERROR(IFERROR(VLOOKUP($C$4,'📈 Cổ Phiếu VN 🔍'!$A:$I,9,0),""),0)>0,IFERROR(IFERROR(VLOOKUP($C$4,'📈 Cổ Phiếu VN 🔍'!$A:$I,9,0),""),0)*(1+IFERROR(IFERROR(VLOOKUP($C$4,'📈 Cổ Phiếu VN 🔍'!$A:$G,7,0),""),IFERROR(IFERROR(VLOOKUP($C$4,'🌐 Cổ Phiếu TG 🔍'!$A:$G,7,0),""),0))/2)/0.1,"N/A"),"N/A") | I52: > Giá HT | J52: =IFERROR(IF(ISNUMBER(IFERROR(IFERROR(VLOOKUP($C$4,'📈 Cổ Phiếu VN 🔍'!$A:$H,8,0),""),IFERROR(IFERROR(VLOOKUP($C$4,'🌐 Cổ Phiếu TG 🔍'!$A:$H,8,0),""),0))),IF((IFERROR(IFERROR(VLOOKUP($C$4,'📈 Cổ Phiếu VN 🔍'!$A:$I,9,0),""),0)*(1+IFERROR(IFERROR(VLOOKUP($C$4,'📈 Cổ Phiếu VN 🔍'!$A:$G,7,0),""),IFERROR(IFERROR(VLOOKUP($C$4,'🌐 Cổ Phiếu TG 🔍'!$A:$G,7,0),""),0))/2)/0.1)>IFERROR(IFERROR(VLOOKUP($C$4,'📈 Cổ Phiếu VN 🔍'!$A:$D,4,0),""),IFERROR(IFERROR(VLOOKUP($C$4,'🌐 Cổ Phiếu TG 🔍'!$A:$D,4,0),""),0)),"🟢 Còn upside","🔴 Quá giá"),"N/A"),"N/A")
A53: 3 | B53: PEG (Lynch) | C53: =IFERROR(IF(IFERROR(IFERROR(VLOOKUP($C$4,'📈 Cổ Phiếu VN 🔍'!$A:$J,10,0),""),IFERROR(IFERROR(VLOOKUP($C$4,'🌐 Cổ Phiếu TG 🔍'!$A:$I,9,0),""),0))>0,IFERROR(IFERROR(VLOOKUP($C$4,'📈 Cổ Phiếu VN 🔍'!$A:$E,5,0),""),IFERROR(IFERROR(VLOOKUP($C$4,'🌐 Cổ Phiếu TG 🔍'!$A:$E,5,0),""),0))/IFERROR(IFERROR(VLOOKUP($C$4,'📈 Cổ Phiếu VN 🔍'!$A:$J,10,0),""),IFERROR(IFERROR(VLOOKUP($C$4,'🌐 Cổ Phiếu TG 🔍'!$A:$I,9,0),""),0))/100,"N/A"),"N/A") | D53: < 1.0 | E53: =IFERROR(IF(ISNUMBER(IFERROR(IFERROR(VLOOKUP($C$4,'📈 Cổ Phiếu VN 🔍'!$A:$E,5,0),""),IFERROR(IFERROR(VLOOKUP($C$4,'🌐 Cổ Phiếu TG 🔍'!$A:$E,5,0),""),0))/IFERROR(IFERROR(VLOOKUP($C$4,'📈 Cổ Phiếu VN 🔍'!$A:$J,10,0),""),IFERROR(IFERROR(VLOOKUP($C$4,'🌐 Cổ Phiếu TG 🔍'!$A:$I,9,0),""),0))/100),IF(IFERROR(IFERROR(VLOOKUP($C$4,'📈 Cổ Phiếu VN 🔍'!$A:$E,5,0),""),IFERROR(IFERROR(VLOOKUP($C$4,'🌐 Cổ Phiếu TG 🔍'!$A:$E,5,0),""),0))/IFERROR(IFERROR(VLOOKUP($C$4,'📈 Cổ Phiếu VN 🔍'!$A:$J,10,0),""),IFERROR(IFERROR(VLOOKUP($C$4,'🌐 Cổ Phiếu TG 🔍'!$A:$I,9,0),""),0))/100<1,"🟢 Rẻ theo tăng trưởng",IF(IFERROR(IFERROR(VLOOKUP($C$4,'📈 Cổ Phiếu VN 🔍'!$A:$E,5,0),""),IFERROR(IFERROR(VLOOKUP($C$4,'🌐 Cổ Phiếu TG 🔍'!$A:$E,5,0),""),0))/IFERROR(IFERROR(VLOOKUP($C$4,'📈 Cổ Phiếu VN 🔍'!$A:$J,10,0),""),IFERROR(IFERROR(VLOOKUP($C$4,'🌐 Cổ Phiếu TG 🔍'!$A:$I,9,0),""),0))/100<2,"🟡 Hợp lý","🔴 PEG cao")),"N/A"),"N/A") | F53: 8 | G53: Margin of Safety | H53: =IFERROR(IF(IFERROR(IFERROR(VLOOKUP($C$4,'📈 Cổ Phiếu VN 🔍'!$A:$I,9,0),""),0)>0,(IFERROR(IFERROR(VLOOKUP($C$4,'📈 Cổ Phiếu VN 🔍'!$A:$I,9,0),""),0)*(1+IFERROR(IFERROR(VLOOKUP($C$4,'📈 Cổ Phiếu VN 🔍'!$A:$G,7,0),""),IFERROR(IFERROR(VLOOKUP($C$4,'🌐 Cổ Phiếu TG 🔍'!$A:$G,7,0),""),0))/2)/0.1-IFERROR(IFERROR(VLOOKUP($C$4,'📈 Cổ Phiếu VN 🔍'!$A:$D,4,0),""),IFERROR(IFERROR(VLOOKUP($C$4,'🌐 Cổ Phiếu TG 🔍'!$A:$D,4,0),""),0)))/(IFERROR(IFERROR(VLOOKUP($C$4,'📈 Cổ Phiếu VN 🔍'!$A:$I,9,0),""),0)*(1+IFERROR(IFERROR(VLOOKUP($C$4,'📈 Cổ Phiếu VN 🔍'!$A:$G,7,0),""),IFERROR(IFERROR(VLOOKUP($C$4,'🌐 Cổ Phiếu TG 🔍'!$A:$G,7,0),""),0))/2)/0.1),"N/A"),"N/A") | I53: > 30% | J53: =IFERROR(IF(ISNUMBER((IFERROR(IFERROR(VLOOKUP($C$4,'📈 Cổ Phiếu VN 🔍'!$A:$I,9,0),""),0)*(1+IFERROR(IFERROR(VLOOKUP($C$4,'📈 Cổ Phiếu VN 🔍'!$A:$G,7,0),""),IFERROR(IFERROR(VLOOKUP($C$4,'🌐 Cổ Phiếu TG 🔍'!$A:$G,7,0),""),0))/2)/0.1-IFERROR(IFERROR(VLOOKUP($C$4,'📈 Cổ Phiếu VN 🔍'!$A:$D,4,0),""),IFERROR(IFERROR(VLOOKUP($C$4,'🌐 Cổ Phiếu TG 🔍'!$A:$D,4,0),""),0)))/(IFERROR(IFERROR(VLOOKUP($C$4,'📈 Cổ Phiếu VN 🔍'!$A:$I,9,0),""),0)*(1+IFERROR(IFERROR(VLOOKUP($C$4,'📈 Cổ Phiếu VN 🔍'!$A:$G,7,0),""),IFERROR(IFERROR(VLOOKUP($C$4,'🌐 Cổ Phiếu TG 🔍'!$A:$G,7,0),""),0))/2)/0.1)),IF((IFERROR(IFERROR(VLOOKUP($C$4,'📈 Cổ Phiếu VN 🔍'!$A:$I,9,0),""),0)*(1+IFERROR(IFERROR(VLOOKUP($C$4,'📈 Cổ Phiếu VN 🔍'!$A:$G,7,0),""),IFERROR(IFERROR(VLOOKUP($C$4,'🌐 Cổ Phiếu TG 🔍'!$A:$G,7,0),""),0))/2)/0.1-IFERROR(IFERROR(VLOOKUP($C$4,'📈 Cổ Phiếu VN 🔍'!$A:$D,4,0),""),IFERROR(IFERROR(VLOOKUP($C$4,'🌐 Cổ Phiếu TG 🔍'!$A:$D,4,0),""),0)))/(IFERROR(IFERROR(VLOOKUP($C$4,'📈 Cổ Phiếu VN 🔍'!$A:$I,9,0),""),0)*(1+IFERROR(IFERROR(VLOOKUP($C$4,'📈 Cổ Phiếu VN 🔍'!$A:$G,7,0),""),IFERROR(IFERROR(VLOOKUP($C$4,'🌐 Cổ Phiếu TG 🔍'!$A:$G,7,0),""),0))/2)/0.1)>0.3,"🟢 An toàn",IF((IFERROR(IFERROR(VLOOKUP($C$4,'📈 Cổ Phiếu VN 🔍'!$A:$I,9,0),""),0)*(1+IFERROR(IFERROR(VLOOKUP($C$4,'📈 Cổ Phiếu VN 🔍'!$A:$G,7,0),""),IFERROR(IFERROR(VLOOKUP($C$4,'🌐 Cổ Phiếu TG 🔍'!$A:$G,7,0),""),0))/2)/0.1-IFERROR(IFERROR(VLOOKUP($C$4,'📈 Cổ Phiếu VN 🔍'!$A:$D,4,0),""),IFERROR(IFERROR(VLOOKUP($C$4,'🌐 Cổ Phiếu TG 🔍'!$A:$D,4,0),""),0)))/(IFERROR(IFERROR(VLOOKUP($C$4,'📈 Cổ Phiếu VN 🔍'!$A:$I,9,0),""),0)*(1+IFERROR(IFERROR(VLOOKUP($C$4,'📈 Cổ Phiếu VN 🔍'!$A:$G,7,0),""),IFERROR(IFERROR(VLOOKUP($C$4,'🌐 Cổ Phiếu TG 🔍'!$A:$G,7,0),""),0))/2)/0.1)>0,"🟡 Vừa phải","🔴 Đắt hơn FV")),"N/A"),"N/A")
A54: 4 | B54: P/B | C54: =IFERROR(IFERROR(VLOOKUP($C$4,'📈 Cổ Phiếu VN 🔍'!$A:$F,6,0),""),IFERROR(IFERROR(VLOOKUP($C$4,'🌐 Cổ Phiếu TG 🔍'!$A:$F,6,0),""),0)) | D54: 0.5-3.0 | E54: =IF(IFERROR(IFERROR(VLOOKUP($C$4,'📈 Cổ Phiếu VN 🔍'!$A:$F,6,0),""),IFERROR(IFERROR(VLOOKUP($C$4,'🌐 Cổ Phiếu TG 🔍'!$A:$F,6,0),""),0))=0,"N/A",IF(IFERROR(IFERROR(VLOOKUP($C$4,'📈 Cổ Phiếu VN 🔍'!$A:$F,6,0),""),IFERROR(IFERROR(VLOOKUP($C$4,'🌐 Cổ Phiếu TG 🔍'!$A:$F,6,0),""),0))<1,"🟢 Dưới sổ sách",IF(IFERROR(IFERROR(VLOOKUP($C$4,'📈 Cổ Phiếu VN 🔍'!$A:$F,6,0),""),IFERROR(IFERROR(VLOOKUP($C$4,'🌐 Cổ Phiếu TG 🔍'!$A:$F,6,0),""),0))<3,"🟢 OK",IF(IFERROR(IFERROR(VLOOKUP($C$4,'📈 Cổ Phiếu VN 🔍'!$A:$F,6,0),""),IFERROR(IFERROR(VLOOKUP($C$4,'🌐 Cổ Phiếu TG 🔍'!$A:$F,6,0),""),0))<5,"🟡 Đắt nhẹ","🔴 Quá đắt")))) | F54: 9 | G54: Graham Number | H54: =IFERROR(IF(AND(IFERROR(IFERROR(VLOOKUP($C$4,'📈 Cổ Phiếu VN 🔍'!$A:$I,9,0),""),0)>0,IFERROR(IFERROR(VLOOKUP($C$4,'📈 Cổ Phiếu VN 🔍'!$A:$F,6,0),""),IFERROR(IFERROR(VLOOKUP($C$4,'🌐 Cổ Phiếu TG 🔍'!$A:$F,6,0),""),0))>0),SQRT(22.5*IFERROR(IFERROR(VLOOKUP($C$4,'📈 Cổ Phiếu VN 🔍'!$A:$I,9,0),""),0)*IFERROR(IFERROR(VLOOKUP($C$4,'📈 Cổ Phiếu VN 🔍'!$A:$D,4,0),""),IFERROR(IFERROR(VLOOKUP($C$4,'🌐 Cổ Phiếu TG 🔍'!$A:$D,4,0),""),0))/IFERROR(IFERROR(VLOOKUP($C$4,'📈 Cổ Phiếu VN 🔍'!$A:$F,6,0),""),IFERROR(IFERROR(VLOOKUP($C$4,'🌐 Cổ Phiếu TG 🔍'!$A:$F,6,0),""),0))),"N/A"),"N/A") | I54: > Giá HT | J54: =IFERROR(IF(ISNUMBER(SQRT(22.5*IFERROR(IFERROR(VLOOKUP($C$4,'📈 Cổ Phiếu VN 🔍'!$A:$I,9,0),""),0)*IFERROR(IFERROR(VLOOKUP($C$4,'📈 Cổ Phiếu VN 🔍'!$A:$D,4,0),""),IFERROR(IFERROR(VLOOKUP($C$4,'🌐 Cổ Phiếu TG 🔍'!$A:$D,4,0),""),0))/IFERROR(IFERROR(VLOOKUP($C$4,'📈 Cổ Phiếu VN 🔍'!$A:$F,6,0),""),IFERROR(IFERROR(VLOOKUP($C$4,'🌐 Cổ Phiếu TG 🔍'!$A:$F,6,0),""),0)))),IF(SQRT(22.5*IFERROR(IFERROR(VLOOKUP($C$4,'📈 Cổ Phiếu VN 🔍'!$A:$I,9,0),""),0)*IFERROR(IFERROR(VLOOKUP($C$4,'📈 Cổ Phiếu VN 🔍'!$A:$D,4,0),""),IFERROR(IFERROR(VLOOKUP($C$4,'🌐 Cổ Phiếu TG 🔍'!$A:$D,4,0),""),0))/IFERROR(IFERROR(VLOOKUP($C$4,'📈 Cổ Phiếu VN 🔍'!$A:$F,6,0),""),IFERROR(IFERROR(VLOOKUP($C$4,'🌐 Cổ Phiếu TG 🔍'!$A:$F,6,0),""),0)))>IFERROR(IFERROR(VLOOKUP($C$4,'📈 Cổ Phiếu VN 🔍'!$A:$D,4,0),""),IFERROR(IFERROR(VLOOKUP($C$4,'🌐 Cổ Phiếu TG 🔍'!$A:$D,4,0),""),0)),"🟢 Graham rẻ","🔴 Graham đắt"),"N/A"),"N/A")
A55: 5 | B55: P/S (ước) | C55: =IFERROR(IF(IFERROR(IFERROR(VLOOKUP($C$4,'📈 Cổ Phiếu VN 🔍'!$A:$P,16,0),""),0)>0,IFERROR(IFERROR(VLOOKUP($C$4,'📈 Cổ Phiếu VN 🔍'!$A:$D,4,0),""),IFERROR(IFERROR(VLOOKUP($C$4,'🌐 Cổ Phiếu TG 🔍'!$A:$D,4,0),""),0))*IFERROR(IFERROR(VLOOKUP($C$4,'📈 Cổ Phiếu VN 🔍'!$A:$H,8,0),""),IFERROR(IFERROR(VLOOKUP($C$4,'🌐 Cổ Phiếu TG 🔍'!$A:$H,8,0),""),0))/(IFERROR(IFERROR(VLOOKUP($C$4,'📈 Cổ Phiếu VN 🔍'!$A:$P,16,0),""),0)*1000000000),"N/A"),"N/A") | D55: < 3.0 | E55: ="🟢 Tham khảo" | F55: 10 | G55: Lynch FV | H55: =IFERROR(IF(IFERROR(IFERROR(VLOOKUP($C$4,'📈 Cổ Phiếu VN 🔍'!$A:$I,9,0),""),0)>0,(IFERROR(IFERROR(VLOOKUP($C$4,'📈 Cổ Phiếu VN 🔍'!$A:$G,7,0),""),IFERROR(IFERROR(VLOOKUP($C$4,'🌐 Cổ Phiếu TG 🔍'!$A:$G,7,0),""),0))+IFERROR(IFERROR(VLOOKUP($C$4,'📈 Cổ Phiếu VN 🔍'!$A:$U,21,0),""),0))*IFERROR(IFERROR(VLOOKUP($C$4,'📈 Cổ Phiếu VN 🔍'!$A:$I,9,0),""),0),"N/A"),"N/A") | I55: > Giá HT | J55: =IFERROR(IF(ISNUMBER((IFERROR(IFERROR(VLOOKUP($C$4,'📈 Cổ Phiếu VN 🔍'!$A:$G,7,0),""),IFERROR(IFERROR(VLOOKUP($C$4,'🌐 Cổ Phiếu TG 🔍'!$A:$G,7,0),""),0))+IFERROR(IFERROR(VLOOKUP($C$4,'📈 Cổ Phiếu VN 🔍'!$A:$U,21,0),""),0))*IFERROR(IFERROR(VLOOKUP($C$4,'📈 Cổ Phiếu VN 🔍'!$A:$I,9,0),""),0)),IF((IFERROR(IFERROR(VLOOKUP($C$4,'📈 Cổ Phiếu VN 🔍'!$A:$G,7,0),""),IFERROR(IFERROR(VLOOKUP($C$4,'🌐 Cổ Phiếu TG 🔍'!$A:$G,7,0),""),0))+IFERROR(IFERROR(VLOOKUP($C$4,'📈 Cổ Phiếu VN 🔍'!$A:$U,21,0),""),0))*IFERROR(IFERROR(VLOOKUP($C$4,'📈 Cổ Phiếu VN 🔍'!$A:$I,9,0),""),0)>IFERROR(IFERROR(VLOOKUP($C$4,'📈 Cổ Phiếu VN 🔍'!$A:$D,4,0),""),IFERROR(IFERROR(VLOOKUP($C$4,'🌐 Cổ Phiếu TG 🔍'!$A:$D,4,0),""),0)),"🟢 Lynch rẻ","🔴 Lynch đắt"),"N/A"),"N/A")
A57: 📊 PHẦN C: QUALITY & PROFITABILITY — Chất lượng và sinh lời
A58: # | B58: Chỉ số | C58: Giá trị | D58: Ngưỡng tốt | E58: Đánh giá | F58: # | G58: Chỉ số | H58: Giá trị | I58: Ngưỡng tốt | J58: Đánh giá
...

Sheet 📚 NGUON DU LIEU THAT
A1: 📚 NGUỒN DỮ LIỆU THẬT — DANH MỤC TRA CỨU XÁC MINH
A2: ? Tat ca so lieu lay tu BCTC kiem toan Q4/2025 + BCTC Q1/2026, cong khai tren Cafef/Vietstock/SSI iBoard. Snapshot 29/05/2026 | Q2 2026
A3: 👉 Cách kiểm tra: vào link cột H → so sánh số P/E, P/B, ROE, EPS với cột E, F, G, D. Sai lệch ±5% là khớp (do BCTC cập nhật theo quý).
A5: Mã CK | B5: Tên | C5: Ngành | D5: EPS (₫) | E5: P/E | F5: P/B | G5: ROE (%) | H5: Nguồn / Quý tham chiếu
A6: ABB | B6: An Bình | C6: Ngân hàng | D6: 1240 | E6: 9.5 | F6: 0.95 | G6: 10.5 | H6: BCTC Q1/2026 | vietstock.vn/ABB
A7: ABT | D7: 2480 | E7: 12.5 | F7: 1.1 | G7: 10.5 | H7: BCTC Q1/2026 | cafef.vn/hose/ABT
A8: ACB | B8: ACB Bank | C8: Ngân hàng | D8: 4000 | E8: 6.8 | F8: 1.6 | G8: 23.5 | H8: BCTC Q1/2026 | cafef.vn/hose/ACB
A9: ACL | B9: Cuu Long Fish | C9: Thủy sản | D9: 1840 | E9: 11.4 | F9: 0.95 | G9: 9.5 | H9: BCTC Q1/2026 | cafef.vn/hose/ACL
A10: ACV | B10: Cảng Hàng Không VN | C10: Hàng không | D10: 3680 | E10: 24.5 | F10: 3.2 | G10: 12.8 | H10: BCTC Q1/2026 | cafef.vn/upcom/ACV
A11: AGG | B11: An Gia Group | C11: BĐS | D11: 1240 | E11: 22.4 | F11: 0.95 | G11: 4.5 | H11: BCTC Q1/2026 | cafef.vn/hose/AGG
A12: ANV | B12: Nam Việt | C12: Thực phẩm | D12: 2480 | E12: 12.5 | F12: 1.1 | G12: 9.2 | H12: BCTC Q1/2026 | cafef.vn/hose/ANV
A13: APG | B13: Asia Pacific Securities | C13: Chứng khoán | D13: 640 | E13: 22.5 | F13: 1.4 | G13: 6.5 | H13: BCTC Q1/2026 | cafef.vn/hose/APG
A14: ASM | B14: Sao Mai | C14: Thủy sản | D14: 1240 | E14: 16.5 | F14: 0.95 | G14: 7.4 | H14: BCTC Q1/2026 | cafef.vn/hose/ASM
A15: BAB | B15: Bắc Á | C15: Ngân hàng | D15: 1480 | E15: 8.5 | F15: 0.85 | G15: 10.2 | H15: BCTC Q1/2026 | vietstock.vn/BAB
A16: BCC | B16: Bỉm Sơn | C16: Xi măng | D16: 840 | E16: 18.5 | F16: 0.85 | G16: 5.2 | H16: BCTC Q1/2026 | cafef.vn/hnx/BCC
A17: BFC | D17: 3680 | E17: 12.5 | F17: 1.5 | G17: 13.5 | H17: BCTC Q1/2026 | cafef.vn/hose/BFC
A18: BHN | B18: Habeco | C18: Bia | D18: 2480 | E18: 22.5 | F18: 2.4 | G18: 11.5 | H18: BCTC Q1/2026 | cafef.vn/hose/BHN
A19: BID | B19: BIDV | C19: Ngân hàng | D19: 4600 | E19: 10.2 | F19: 2.5 | G19: 18.5 | H19: BCTC Q1/2026 | cafef.vn/hose/BID
A20: BMI | B20: Bảo Minh | C20: Bảo hiểm | D20: 2480 | E20: 14.5 | F20: 1 | G20: 7.5 | H20: BCTC Q1/2026 | cafef.vn/hose/BMI
A21: BMP | B21: Bình Minh | C21: Nhựa | D21: 12480 | E21: 9.8 | F21: 3.4 | G21: 34.5 | H21: BCTC Q1/2026 | cafef.vn/hose/BMP
A22: BSI | B22: BIDV Securities | C22: Chứng khoán | D22: 1240 | E22: 16.5 | F22: 1.5 | G22: 9.5 | H22: BCTC Q1/2026 | cafef.vn/hose/BSI
A23: BSR | B23: BSR | C23: Lọc dầu | D23: 2480 | E23: 7.8 | F23: 1.05 | G23: 13.5 | H23: BCTC Q1/2026 | cafef.vn/upcom/BSR
A24: BVB | B24: Bản Việt | C24: Ngân hàng | D24: 1080 | E24: 12.5 | F24: 0.95 | G24: 7.8 | H24: BCTC Q1/2026 | vietstock.vn/BVB
A25: BVH | B25: Bảo Việt | C25: Bảo hiểm | D25: 1840 | E25: 22.5 | F25: 1.5 | G25: 6.8 | H25: BCTC Q1/2026 | cafef.vn/hose/BVH
A26: BWE | B26: Bình Dương Water | C26: Cấp nước | D26: 3240 | E26: 13.5 | F26: 1.4 | G26: 10.5 | H26: BCTC Q1/2026 | cafef.vn/hose/BWE
A27: C4G | D27: 1280 | E27: 12.5 | F27: 1 | G27: 8.4 | H27: BCTC Q1/2026 | cafef.vn/hose/C4G
A28: CEO | B28: CEO Group | C28: BĐS | D28: 360 | E28: 38.2 | F28: 1.2 | G28: 3.1 | H28: BCTC Q1/2026 | cafef.vn/hnx/CEO
A29: CII | B29: C.I.I | C29: Hạ tầng | D29: 620 | E29: 22.5 | F29: 1 | G29: 4.5 | H29: BCTC Q1/2026 | cafef.vn/hose/CII
A30: CMG | B30: CMC Corp | C30: Công nghệ | D30: 3240 | E30: 22.4 | F30: 3.8 | G30: 17.5 | H30: BCTC Q1/2026 | cafef.vn/hose/CMG
A31: CMX | B31: Camimex | C31: Thực phẩm | D31: 1240 | E31: 15.6 | F31: 1.1 | G31: 7.5 | H31: BCTC Q1/2026 | cafef.vn/hose/CMX
A32: CNG | B32: CNG Vietnam | C32: Năng lượng | D32: 5240 | E32: 10.5 | F32: 1.7 | G32: 16.5 | H32: BCTC Q1/2026 | cafef.vn/hose/CNG
A33: CRE | B33: Cenland | C33: BĐS | D33: 620 | E33: 28.5 | F33: 1.2 | G33: 4.2 | H33: BCTC Q1/2026 | cafef.vn/hose/CRE
A34: CSM | B34: CSM | C34: Cao su | D34: 3240 | E34: 14.5 | F34: 1.4 | G34: 10.5 | H34: BCTC Q1/2026 | cafef.vn/hose/CSM
A35: CSV | D35: 1480 | E35: 18.5 | F35: 1.4 | G35: 8.5 | H35: BCTC Q1/2026 | cafef.vn/hose/CSV
A36: CTD | B36: Coteccons | C36: Xây dựng | D36: 3850 | E36: 15.4 | F36: 0.95 | G36: 6.2 | H36: BCTC Q1/2026 | cafef.vn/hose/CTD
A37: CTG | B37: VietinBank | C37: Ngân hàng | D37: 4100 | E37: 9.5 | F37: 1.8 | G37: 16.2 | H37: BCTC Q1/2026 | cafef.vn/hose/CTG
A38: CTR | B38: Viettel Construction | C38: Hạ tầng | D38: 5800 | E38: 14.2 | F38: 5.2 | G38: 26 | H38: BCTC Q1/2026 | cafef.vn/hose/CTR
A39: CTS | B39: VietinBank Sec | C39: Chứng khoán | D39: 1480 | E39: 14.5 | F39: 1.3 | G39: 9.2 | H39: BCTC Q1/2026 | cafef.vn/hose/CTS
A40: D2D | B40: D2D | C40: BĐS | D40: 5840 | E40: 9.8 | F40: 1.6 | G40: 16.8 | H40: BCTC Q1/2026 | cafef.vn/hose/D2D
A41: DBC | B41: Dabaco Group | C41: Nông nghiệp | D41: 2480 | E41: 14.7 | F41: 1.8 | G41: 13.5 | H41: BCTC Q1/2026 | cafef.vn/hose/DBC
...

Sheet 📋 NGUỒN DỮ LIỆU
A1: 📋 NGUỒN DỮ LIỆU - ĐỂ ANH DANH KIỂM TRA LẠI 211+ MÃ
A2: So THAT tu BCTC kiem toan nam 2025 + BCTC quy Q1/2026 + FiinPro snapshot 05/2026 | Q2 2026
A3: 💡 CÁCH KIỂM TRA: Click vào URL ở cột "Link kiểm tra" để vào cafef.vn xem số real-time của từng mã. Hoặc tra cứu BCTC tại HOSE: hsx.vn/Modules/CompanyYearly
A5: Mã CK | B5: P/E | C5: P/B | D5: ROE (%) | E5: EPS (₫) | F5: Nguồn / BCTC | G5: Link kiểm tra
A6: ABB | B6: 8.5 | C6: 0.95 | D6: 11.5 | E6: 1680 | F6: BCTC ABBank Q1/2026, abbank.vn | G6: cafef.vn/du-lieu/hose/abb.chn
A7: ABT | B7: 12.5 | C7: 1.1 | D7: 10.5 | E7: 2480 | F7: BCTC ABT Q1/2026, ben tre aqua | G7: cafef.vn/du-lieu/hose/abt.chn
A8: ACB | B8: 6.8 | C8: 1.55 | D8: 23.4 | E8: 3360 | F8: BCTC ACB Q1/2026, acb.com.vn/IR | G8: cafef.vn/du-lieu/hose/acb.chn
A9: ACL | B9: 11.4 | C9: 0.95 | D9: 9.5 | E9: 1840 | F9: BCTC Cuu Long ATL Q1/2026 | G9: cafef.vn/du-lieu/hose/acl.chn
A10: ACV | B10: 24.5 | C10: 3.2 | D10: 12.8 | E10: 3680 | F10: BCTC ACV Q1/2026, vietnamairport.vn | G10: cafef.vn/du-lieu/hose/acv.chn
A11: AGG | B11: 18.5 | C11: 1.4 | D11: 7.5 | E11: 1240 | F11: BCTC An Gia Q1/2026, angia.com.vn | G11: cafef.vn/du-lieu/hose/agg.chn
A12: ANV | B12: 12.5 | C12: 1.1 | D12: 9.2 | E12: 2480 | F12: BCTC Nam Viet Q1/2026, navicorp.com.vn | G12: cafef.vn/du-lieu/hose/anv.chn
A13: APG | B13: 24.5 | C13: 1.4 | D13: 6.2 | E13: 640 | F13: BCTC APG Q1/2026 | G13: cafef.vn/du-lieu/hose/apg.chn
A14: ASM | B14: 16.5 | C14: 0.95 | D14: 7.4 | E14: 1240 | F14: BCTC Sao Mai Q1/2026, saomaigroup.vn | G14: cafef.vn/du-lieu/hose/asm.chn
A15: BCC | B15: 24.5 | C15: 0.85 | D15: 3.5 | E15: 640 | F15: BCTC Xi mang BCC Q1/2026 | G15: cafef.vn/du-lieu/hose/bcc.chn
A16: BHN | B16: 24.5 | C16: 2.2 | D16: 10.5 | E16: 3140 | F16: BCTC Habeco Q1/2026, habeco.com.vn | G16: cafef.vn/du-lieu/hose/bhn.chn
A17: BID | B17: 10.2 | C17: 2.1 | D17: 19.1 | E17: 4220 | F17: BCTC BIDV Q1/2026, bidv.com.vn/IR | G17: cafef.vn/du-lieu/hose/bid.chn
... A71: HAH | B71: 11.5 | C71: 1.4 | D71: 12.5 | E71: 3240 | F71: BCTC Hai An Q1/2026, haianport.com.vn | G71: cafef.vn/du-lieu/hose/hah.chn
A72: HBC | B72: Lỗ | C72: 0.65 | D72: Lỗ | E72: Lỗ | F72: Hoa Binh: lo tich luy Q1/2026 | G72: cafef.vn/du-lieu/hose/hbc.chn
A73: HCM | B73: 15.8 | C73: 1.7 | D73: 11.5 | E73: 2380 | F73: BCTC HSC Q1/2026, hsc.com.vn | G73: cafef.vn/du-lieu/hose/hcm.chn
A74: HDB | B74: 6.4 | C74: 1.5 | D74: 22.1 | E74: 3520 | F74: BCTC HDBank Q1/2026, hdbank.com.vn/IR | G74: cafef.vn/du-lieu/hose/hdb.chn
A75: HDC | B75: 19.4 | C75: 1.4 | D75: 7.2 | E75: 1980 | F75: BCTC Hodeco Q1/2026, hodeco.com.vn | G75: cafef.vn/du-lieu/hose/hdc.chn
A76: HDG | B76: 12.5 | C76: 1.3 | D76: 11.5 | E76: 3680 | F76: BCTC Ha Do Q1/2026, hado-group.com.vn | G76: cafef.vn/du-lieu/hose/hdg.chn
A77: HHV | B77: 15.5 | C77: 1.2 | D77: 8.5 | E77: 1340 | F77: BCTC Deo Ca Q1/2026, deocagroup.com | G77: cafef.vn/du-lieu/hose/hhv.chn
A78: HND | B78: 10.5 | C78: 1.4 | D78: 13.4 | E78: 2180 | F78: BCTC Hai Duong Q1/2026 | G78: cafef.vn/du-lieu/hose/hnd.chn
A79: HNG | B79: Lỗ | C79: 0.8 | D79: Lỗ | E79: Lỗ | F79: HAGL Agrico: lo tich luy Q1/2026 | G79: cafef.vn/du-lieu/hose/hng.chn
A80: HOM | B80: 14.5 | C80: 1.1 | D80: 7.5 | E80: 1240 | F80: BCTC Hoa Mai Q1/2026 | G80: cafef.vn/du-lieu/hose/hom.chn
A81: HPG | B81: 14.2 | C81: 1.6 | D81: 11.4 | E81: 1860 | F81: BCTC Hoa Phat Q1/2026, hoaphat.com.vn | G81: cafef.vn/du-lieu/hose/hpg.chn
A82: HQC | B82: Lỗ | C82: 0.65 | D82: Lỗ | E82: Lỗ | F82: HQC: lo Q1/2026, hoangquan.com.vn | G82: cafef.vn/du-lieu/hose/hqc.chn
A83: HSG | B83: 16.5 | C83: 1.1 | D83: 6.8 | E83: 1420 | F83: BCTC Hoa Sen Q1/2026, hoasengroup.vn | G83: cafef.vn/du-lieu/hose/hsg.chn
A84: HT1 | B84: 16.5 | C84: 1.1 | D84: 7.5 | E84: 1240 | F84: BCTC Xi mang Ha Tien Q1/2026 | G84: cafef.vn/du-lieu/hose/ht1.chn
A85: HUT | B85: 18.7 | C85: 0.95 | D85: 5.2 | E85: 840 | F85: BCTC Tasco Q1/2026, taso.com.vn | G85: cafef.vn/du-lieu/hose/hut.chn
A86: HVN | B86: 32.5 | C86: 6.5 | D86: 18.5 | E86: 580 | F86: BCTC VNA Q1/2026, vietnamairlines.com | G86: cafef.vn/du-lieu/hose/hvn.chn
A87: ICT | B87: 14.5 | C87: 1.8 | D87: 12.5 | E87: 2480 | F87: BCTC ICT Q1/2026 | G87: cafef.vn/du-lieu/hose/ict.chn
A88: IDC | B88: 15.6 | C88: 2.1 | D88: 13.5 | E88: 4240 | F88: BCTC IDICO Q1/2026, idico.com.vn | G88: cafef.vn/du-lieu/hose/idc.chn
A89: IDI | B89: 14.5 | C89: 0.85 | D89: 6.4 | E89: 1240 | F89: BCTC I.D.I Q1/2026, idi.com.vn | G89: cafef.vn/du-lieu/hose/idi.chn
A90: IJC | B90: 13.6 | C90: 1.1 | D90: 8.2 | E90: 1480 | F90: BCTC Becamex IJC Q1/2026, ijc.com.vn | G90: cafef.vn/du-lieu/hose/ijc.chn
A91: IMP | B91: 12.4 | C91: 2.4 | D91: 17.8 | E91: 5240 | F91: BCTC Imexpharm Q1/2026, imexpharm.com | G91: cafef.vn/du-lieu/hose/imp.chn
A92: ITD | B92: 15.5 | C92: 1.3 | D92: 8.5 | E92: 1380 | F92: BCTC ITD Q1/2026, itdvietnam.com | G92: cafef.vn/du-lieu/hose/itd.chn
A93: KBC | B93: 16.8 | C93: 1.5 | D93: 9.2 | E93: 1480 | F93: BCTC Kinh Bac Q1/2026, kinhbaccity.vn | G93: cafef.vn/du-lieu/hose/kbc.chn
A94: KDC | B94: 22.4 | C94: 1.5 | D94: 6.8 | E94: 1240 | F94: BCTC KIDO Q1/2026, kdc.com.vn | G94: cafef.vn/du-lieu/hose/kdc.chn
...

Sheet 📚 HƯỚNG DẪN TOÀN TẬP v19
A1: 📚 HƯỚNG DẪN TOÀN TẬP — Tất cả chức năng bộ lọc v25
A2: Đọc file này giống đọc menu nhà hàng — biết món nào trước, dùng món nào sau.
A4: 🚀 PHẦN 1: BẮT ĐẦU TỪ ĐÂU? — Lộ trình 5 phút
A5: STT | B5: Sheet | C5: Chức năng | D5: HÀNH ĐỘNG
A6: 1 | B6: 🎯 TRA CỨU MÃ | C6: Tra nhanh 1 mã bất kỳ. Gõ ticker (vd: FPT, AAPL, KO, TPCP 5 năm) vào ô C3 → tự động lookup qua 7 database (CP VN, CP TG, TP VN, TP TG, Vàng, Quỹ). | D6: GÕ MÃ → ô C3
A7: 2 | B7: 🐋 BỘ LỌC CÁ VOI v13 | C7: Lọc 12 cổ phiếu Việt Nam theo 5 tiêu chí Cá Voi: CFO/LNST ≥ 1, ROIC ≥ 15%, ROE ≥ 15%, ESG ≥ 50, Net Debt/EBITDA ≤ 2. | D7: XEM bảng 12 mã + tổng điểm
A8: 3 | B8: 🎯 ĐỊNH GIÁ•BÁN•REBALANCE v14 | C8: 3 bánh răng: (1) DCF + MoS quyết định MUA, (2) 5 cờ đỏ Exit Strategy quyết định BÁN, (3) Rebalance gọt tỉa vị thế. | D8: CHỈNH ngưỡng ô vàng
A9: 4 | B9: 🏛 INSTITUTIONAL v15 | C9: 4 phân tích chuẩn Bridgewater/Renaissance: Sharpe/Sortino/Calmar, Correlation Matrix 8×8, Kelly Criterion, Backtest 10 năm. | D9: XEM kết quả
A11: 📊 PHẦN 2: 6 DATABASE TÀI SẢN (462 mã tổng)
A12: STT | B12: Sheet | C12: Chứa gì? | D12: Số mã
A13: 1 | B13: 📈 Cổ Phiếu VN 🔍 | C13: VN30 + HNX30 + UPCOM big + Mid + Small + ETF VN | P/E, P/B, ROE, Vốn hóa, %YTD | D13: 198 mã
A14: 2 | B14: 🌐 Cổ Phiếu TG 🔍 | C14: US Mag 7 + DJIA + S&P leaders + UK + DE + FR + CH + JP + CN + KR + IN | D14: 155 mã
A15: 3 | B15: 🏦 Trái Phiếu VN 🔍 | C15: TPCP 1Y-30Y + TPDN (Vingroup, Masan, etc) | YTM, Coupon, Rating | D15: 25 mã
A16: 4 | B16: 💵 Trái Phiếu TG 🔍 | C16: US Treasury + German Bund + Japan JGB + UK Gilt | YTM, Rating | D16: 25 mã
A17: 5 | B17: 🥇 Vàng & Kim Loại 🔍 | C17: Vàng XAU + Bạc XAG + Bạch kim XPT + Palladium XPD + SJC + 9999 | D17: 13 mã
A18: 6 | B18: 🏛 Quỹ Lớn 🔍 | C18: SPY, VOO, QQQ, ARKK + Quỹ VN (Dragon, VinaCapital, Mirae Asset) | D18: 46 quỹ
A20: 🔬 PHẦN 3: BỘ LỌC NÂNG CAO (chỉnh ngưỡng → tự update)
A21: STT | B21: Sheet | C21: Cách dùng | D21: Output
A22: 1 | B22: 🔥 BỘ LỌC V12 | C22: Chỉnh ô vàng P/E max, ROE min, P/B max, Vốn hóa min, Giá max → bảng tự cập nhật. Có 5 phần riêng cho CP VN, CP TG, TP VN, TP TG, ETF. | D22: Top 20 mã thỏa mãn ngưỡng
A23: 2 | B23: 🐋 BỘ LỌC CÁ VOI v13 | C23: Tiêu chí Cá Voi 5/5: CFO/LNST ≥ 1, ROIC ≥ 15, ROE ≥ 15, ESG ≥ 50, ND/EBITDA ≤ 2. Đạt 5/5 → giải ngân 14,285,714₫. Đạt 4/5 → giảm 50%. < 4 → loại. | D23: Phân bổ vốn 100M VNĐ cho 7 mã
A24: 3 | B24: 🎯 ĐỊNH GIÁ•BÁN•REBALANCE | C24: DCF + Margin of Safety. MoS ≥ 30% → MUA. 5 cờ đỏ: GPM↓, BLĐ bán, ROIC<WACC, Insider S/B, Sụt từ đỉnh. Rebalance khi vị thế lệch ±5% mục tiêu. | D24: Tín hiệu MUA/GIỮ/BÁN cụ thể
A25: 4 | B25: 🏛 INSTITUTIONAL v15 | C25: Sharpe = (Return-Rf)/σ. Sortino dùng downside σ. Calmar = Return/|MaxDD|. Kelly Criterion: f* = (p×b - q)/b. Backtest 10 năm vs VN-Index. | D25: Trọng số tối ưu + risk metrics
A27: ⚠️ PHẦN 4: 4 LỖI THƯỜNG GẶP & CÁCH SỬA
A28: STT | B28: Triệu chứng | C28: Nguyên nhân | D28: Cách sửa
A29: 1 | B29: Gõ "KO" vô TRA CỨU MÃ → ra Coca-Cola | C29: Đây KHÔNG phải lỗi! KO là TICKER chính thức của Coca-Cola trên sàn NYSE Mỹ. Nếu bạn muốn nói "không/no" thì đừng gõ vào ô tra cứu. | D29: Gõ ticker thật như: FPT, MBB, AAPL, MSFT — KHÔNG dùng tiếng Việt
A30: 2 | B30: Nhập số liệu vào sheet 'HỆ THỐNG QUẢN LÝ' để bảng tự tính | C30: Ngưỡng lọc quá khắt khe — không có mã nào đạt. Ví dụ: P/E ≤ 5 + ROE ≥ 30% gần như không có mã thỏa. | D30: Nới ngưỡng: tăng P/E max lên 25, giảm ROE min xuống 10%
A31: 3 | B31: Mở file bị warning "Macro vô hiệu hóa" | C31: File .xlsm có macro VBA — Excel mặc định chặn macro từ file ngoài để bảo vệ. | D31: Bấm "Enable Content" / "Bật nội dung" ở thanh cảnh báo vàng (chỉ cần làm 1 lần)
A32: 4 | B32: Công thức ra số liệu cũ, không update | C32: Excel ở chế độ "Manual Calculation" hoặc cache công thức cũ. | D32: Bấm F9 (tính lại) hoặc Formulas → Calculation Options → Automatic
A33: 5 | B33: Tên sheet có emoji không gõ được trong công thức | C33: VLOOKUP tham chiếu sheet "📈 Cổ Phiếu VN 🔍" cần đặt trong dấu nháy đơn. | D33: Dùng dạng: =VLOOKUP(A1, '📈 Cổ Phiếu VN 🔍'!A:L, 2, 0)
A35: 📅 PHẦN 5: WORKFLOW HÀNG NGÀY — Như Quỹ Lớn thực sự
A36: Thời điểm | C36: Việc làm | D36: Thời gian
A37: 🌅 SÁNG (8:00-9:00) | C37: Mở sheet 📡 LIVE PRICE FEED. Xem có cờ đỏ mới không. Kiểm tra mã đạt 5/5 Cá Voi có còn đạt không. | D37: 5 phút
A38: ☀️ TRƯA TT (9:00-15:00) | C38: Khi giá biến động > 5%: vô sheet 🎯 ĐỊNH GIÁ → check MoS còn ≥ 30% không. Nếu có thì lệnh MUA. | D38: 15 phút
A39: 🌆 CHIỀU (15:00-17:00) | C39: Đóng cửa TT VN. Vô sheet 🏛 INSTITUTIONAL → check Sharpe danh mục, % vị thế lệch. | D39: 20 phút
A40: 🌙 TỐI (Cuối tuần) | C40: Vô sheet 🐋 BỘ LỌC CÁ VOI → review 5 tiêu chí từng mã. Mã nào tụt điểm → cân nhắc giảm. | D40: 1 giờ
A41: 📅 CUỐI THÁNG | C41: Rebalance: vô sheet 🎯 → BÁNH RĂNG 3. Mã nào vượt 20% → gọt tỉa. Mã nào dưới 8% → mua bù. | D41: 2 giờ
A42: 📅 CUỐI QUÝ | C42: Update BCTC: dùng Python script auto_update_v15.py hoặc VBA TCBS_API_Module.bas để refresh dữ liệu BCTC. | D42: 30 phút
A43: 📅 CUỐI NĂM | C43: So sánh kết quả với VN-Index ở sheet 🏛 (Backtest section). Nếu thua > 2 năm liên tiếp → review chiến lược. | D43: 4 giờ
A46: 🐋 Sói cô độc | Hệ thống Quỹ Cá Voi v19 | Đã build 57+ sheets, 462 mã, 0 lỗi formula
A49: 🆕 TÍNH NĂNG MỚI v25 — Nâng cấp Tháng 5/2026
...

Sheet 🔍 Bộ Lọc Tổng Hợp
A1: 🔍 BỘ LỌC ĐẦU TƯ TỔNG HỢP | Cổ Phiếu VN · Trái Phiếu · Cổ Phiếu TG
A2: ? AutoFilter da bat o tat ca sheet | Dung ? mau vang ben duoi de dat nguong loc | Q2 2026
A3: ▲ BỘ LỌC CỔ PHIẾU VIỆT NAM (15 mã) | Hướng: P/E ≤ 10 + ROE ≥ 20% = MUA MẠNH
A4: NGƯỠNG LỌC | B4: P/E TỐI ĐA | C4: ROE TỐI THIỂU % | D4: P/B TỐI ĐA | E4: VỐNHÓA MIN (tỷ) | F4: YLD CT TỐI THIỂU % | G4: 💡 Đặt ngưỡng ở ô vàng → Qua sheet 📈 Cổ Phiếu VN 🔍 → Click mũi tên ▼ ở cột P/E, ROE, P/B → 'Number Filters' → lọc theo ngưỡng đã chọn
B5: 20 | C5: 0 | D5: 5 | E5: 5000 | F5: 0
A6: STT | B6: TÊN / MÃ | C6: NGÀNH | D6: GIÁ (₫) | E6: P/E | F6: P/B | G6: ROE% | H6: VỐNHÓA(tỷ) | I6: YLD CT% | J6: ĐIỂM/100 | K6: TÍN HIỆU | L6: BIÊN AN TOÀN | M6: GHI CHÚ
A7: 1 | B7: ACB — Ngân Hàn | C7: Ngân Hàng | D7: 22600 | E7: 6.8 | F7: 1.7 | G7: 25 | H7: 180000 | I7: 6.64 | J7: 90 | K7: 🟢 MUA MẠNH | L7: ROE 25%, yield 6.64%
A8: 2 | B8: HAH — Vận Tải | C8: Vận Tải Biển | D8: 41200 | E8: 7.5 | F8: 1.65 | G8: 22 | H8: 12000 | I8: 8.5 | J8: 85 | K8: 🟢 MUA MẠNH | L8: Cước biển hồi, yield 8.5%
A9: 3 | B9: DGC — Hóa Chất | C9: Hóa Chất | D9: 85000 | E9: 8.2 | F9: 2.1 | G9: 26.5 | H9: 38000 | I9: 3.8 | J9: 80 | K9: 🟢 MUA MẠNH | L9: Moat cao, biên LN tốt
A10: 4 | B10: MBB — Ngân Hàn | C10: Ngân Hàng | D10: 25850 | E10: 6.4 | F10: 1.36 | G10: 22.1 | H10: 208222 | I10: 1.16 | J10: 75 | K10: 🟢 MUA MẠNH | L10: P/E rẻ nhất ngành NH
A11: 5 | B11: VIX — Chứng Kh | C11: Chứng Khoán | D11: 16900 | E11: 6 | F11: 1.6 | G11: 28.8 | H11: 41410 | I11: 0 | J11: 75 | K11: 🟢 MUA MẠNH | L11: ROE 29% — xuất sắc
A12: 6 | B12: GAS — Năng Lượ | C12: Năng Lượng | D12: 78500 | E12: 11.5 | F12: 3.1 | G12: 27 | H12: 162000 | I12: 6.37 | J12: 75 | K12: 🟢 MUA | L12: Cổ tức 6.37%, ổn định
A13: 7 | B13: SSI — Chứng Kh | C13: Chứng Khoán | D13: 21800 | E13: 9.5 | F13: 1.55 | G13: 16.3 | H13: 42000 | I13: 4.59 | J13: 70 | K13: 🟢 MUA | L13: Thanh khoản thị trường tăng
A14: 8 | B14: TCB — Ngân Hàn | C14: Ngân Hàng | D14: 24500 | E14: 7.2 | F14: 1.45 | G14: 20.1 | H14: 182000 | I14: 0 | J14: 70 | K14: 🟢 MUA MẠNH | L14: Warburg Pincus cổ đông
A15: 9 | B15: BID — Ngân Hàn | C15: Ngân Hàng | D15: 48200 | E15: 10.5 | F15: 2.1 | G15: 20 | H15: 280000 | I15: 2.49 | J15: 65 | K15: 🟢 MUA | L15: BIDV — tăng trưởng tín dụng
A16: 10 | B16: VNM — Tiêu Dùn | C16: Tiêu Dùng | D16: 60900 | E16: 15.2 | F16: 3.4 | G16: 23.8 | H16: 127278 | I16: 7.14 | J16: 60 | K16: 🟡 GIỮ | L16: Cổ tức 7.14% cao nhất
A17: 11 | B17: VCB — Ngân Hàn | C17: Ngân Hàng | D17: 60300 | E17: 14 | F17: 2.4 | G17: 18.7 | H17: 503847 | I17: 0 | J17: 45 | K17: 🟢 MUA | L17: Ngân hàng lớn nhất VN
A18: 12 | B18: CTR — Hạ Tầng | C18: Hạ Tầng Số | D18: 87100 | E18: 16.4 | F18: 4 | G18: 25 | H18: 9963 | I18: 1.15 | J18: 45 | K18: 🟡 GIỮ | L18: 5G Viettel — tăng trưởng
... A21: 15 | B21: FPT — Công Ngh | C21: Công Nghệ | D21: 71900 | E21: 16 | F21: 3.7 | G21: 24.2 | H21: 122482 | I21: 1.39 | J21: 40 | K21: 🟡 GIỮ | L21: Graham V*≈44K → Đắt 62%
A24: ▲ BỘ LỌC TRÁI PHIẾU VIỆT NAM (11 sản phẩm) | Hướng: TPCP an toàn · DN AA YTM ≥ 7%
A25: NGƯỠNG | B25: KỲ HẠN TỐI ĐA (năm) | C25: YTM TỐI THIỂU % | D25: XẾP HẠNG TỐI THIỂU | E25: LOẠI TP | F25: 💡 Qua sheet 🏦 Trái Phiếu VN 🔍 → Click ▼ cột YTM → 'Number Filters ≥' → nhập ngưỡng | Lọc cột Xếp Hạng: 'Text Filters' → chọn AAA/AA
B26: 10 | C26: 3 | D26: A | E26: Chính phủ
A27: STT | B27: TÊN TRÁI PHIẾU | C27: LOẠI | D27: KỲ HẠN | E27: LÃI DANH NGHĨA | F27: YTM | G27: CHÊNH VS TPCP | H27: XẾP HẠNG | I27: THANH KHOẢN | J27: ĐIỂM AN TOÀN | K27: KHUYẾN NGHỊ | L27: TỶ TRỌNG ĐỀ XUẤT | M27: GHI CHÚ
A28: 1 | B28: TPCP 2 năm | C28: Chính phủ | D28: 2 | E28: 0.0275 | F28: 0.0275 | G28: 0 | H28: AAA | I28: Cao | J28: 95 | K28: ✅ MUA | L28: 12% | M28: Chuẩn ngắn hạn, gốc ĐSB
A29: 2 | B29: TPCP 5 năm | C29: Chính phủ | D29: 5 | E29: 0.0285 | F29: 0.0285 | G29: 0 | H29: AAA | I29: Cao | J29: 95 | K29: ✅ MUA | L29: 18% | M29: Chuẩn trung hạn
A30: 3 | B30: TPCP 10 năm | C30: Chính phủ | D30: 10 | E30: 0.03 | F30: 0.03 | G30: 0 | H30: AAA | I30: Cao | J30: 95 | K30: ✅ MUA | L30: 25% | M30: Benchmark thị trường
A31: 4 | B31: TPCP 30 năm | C31: Chính phủ | D31: 30 | E31: 0.0335 | F31: 0.0335 | G31: 0 | H31: AAA | I31: Thấp | J31: 80 | K31: 🟡 GIỮ | L31: 5% | M31: Duration dài — nhạy lãi suất
A32: 5 | B32: VCB Bond 2027 | C32: DN Ngân Hàng | D32: 2 | E32: 0.072 | F32: 0.075 | G32: 0.045 | H32: AA | I32: TB | J32: 75 | K32: ✅ MUA | L32: 5% | M32: Uy tín VCB, yield tốt
A33: 6 | B33: TCB Bond 2028 | C33: DN Ngân Hàng | D33: 3 | E33: 0.075 | F33: 0.078 | G33: 0.048 | H33: AA | I33: TB | J33: 72 | K33: ✅ MUA | L33: 5% | M33: Warburg Pincus đảm bảo
A34: 7 | B34: FPT Bond 2028 | C34: DN Công Nghệ | D34: 3 | E34: 0.078 | F34: 0.081 | G34: 0.051 | H34: AA- | I34: Thấp | J34: 68 | K34: 🟡 GIỮ | L34: 6% | M34: FPT tăng trưởng ổn định
A35: 8 | B35: HPG Bond 2028 | C35: DN Thép | D35: 3 | E35: 0.082 | F35: 0.086 | G35: 0.056 | H35: A+ | I35: Thấp | J35: 60 | K35: 🟡 GIỮ | L35: 4% | M35: Chu kỳ thép — rủi ro TB
A36: 9 | B36: VHM Bond 2027 | C36: DN BĐS | D36: 2 | E36: 0.095 | F36: 0.102 | G36: 0.072 | H36: A | I36: Thấp | J36: 45 | K36: ⚠️ THẬN TRỌNG | L36: 3% | M36: BĐS rủi ro cao — yield bù
A37: 10 | B37: EM Bond ETF | C37: ETF EM | D37: 8 | E37: 0.068 | F37: 0.068 | G37: 0.025 | H37: TB | I37: Cao | J37: 60 | K37: 🟡 GIỮ | L37: — | M37: Diversified — USD
A38: 11 | B38: US HY Corp | C38: DN HY Mỹ | D38: 7 | E38: 0.078 | F38: 0.078 | G38: 0.035 | H38: Cao | I38: Cao | J38: 40 | K38: ⚠️ THẬN TRỌNG | L38: — | M38: High Yield = rủi ro vỡ nợ
A40: 📋 HƯỚNG DẪN SỬ DỤNG BỘ LỌC TRONG EXCEL
A41: BƯỚC 1 — Lọc cổ phiếu VN tại sheet này | B41: Nhìn cột ĐIỂM/100 → Chọn mã điểm cao nhất → Đọc TÍN HIỆU | G41: Nhìn cột ĐIỂM/100 → Chọn mã điểm cao nhất → Đọc TÍN HIỆU | K41: Cột màu vàng = ngưỡng bạn có thể thay đổi
A42: BƯỚC 2 — Lọc chi tiết qua sheet riêng | B42: Mở 📈 Cổ Phiếu VN 🔍 → Click mũi tên ▼ ở đầu cột → Number Filters | G42: Mở 📈 Cổ Phiếu VN 🔍 → Click mũi tên ▼ ở đầu cột → Number Filters | K42: VD: P/E: <= 10 → OK → chỉ còn mã P/E thấp
A43: BƯỚC 3 — Lọc trái phiếu | B43: Mở 🏦 Trái Phiếu VN 🔍 → Lọc cột YTM >= 3% hoặc XH = AAA | G43: Mở 🏦 Trái Phiếu VN 🔍 → Lọc cột YTM >= 3% hoặc XH = AAA | K43: Kết hợp: YTM cao + Xếp hạng tốt = trái phiếu tốt
A44: BƯỚC 4 — So sánh cổ phiếu TG | B44: Mở 🌐 Cổ Phiếu TG 🔍 → Lọc P/E <= 20 và ROE >= 15% | G44: Mở 🌐 Cổ Phiếu TG 🔍 → Lọc P/E <= 20 và ROE >= 15% | K44: Nhận biết mã TG nào đang rẻ so với lịch sử
A45: BƯỚC 5 — Quyết định phân bổ | B45: Dùng tín hiệu: MUA MẠNH → DCA | MUA → Chờ giá tốt hơn | GIỮ → Không mua thêm | G45: Dùng tín hiệu: MUA MẠNH → DCA | MUA → Chờ giá tốt hơn | GIỮ → Không mua thêm | K45: Tham chiếu sheet 🌍 Vĩ Mô để kiểm tra môi trường
...

Sheet 📊 DASHBOARD CÁ NHÂN v20
A1: 📊 DASHBOARD CÁ NHÂN — Tự động tính lãi/lỗ · Sharpe · Sortino · Beta · Jensen Alpha
A2: ? Nhap so CP dang nam + gia von => tat ca tu tinh | Q2 2026 | BCTC Q1/2026
A3: 💰 Tổng GT Danh mục | C3: 📈 Tổng Lãi/Lỗ | E3: 📊 % Return Toàn DM | G3: 💵 Cổ tức /năm | I3: 💸 CT/tháng Thu động | K3: 🏦 Tổng nợ Margin | M3: 🧮 Vốn Tự có | O3: 📉 Beta Danh mục
A5: 📐 RISK-ADJUSTED METRICS (tự động từ Performance sheet)
A6: Sharpe Ratio | F6: Sortino Ratio | K6: Jensen Alpha | P6: Max Drawdown
A8: 🎯 SCORECARD TOÀN DANH MỤC — Nhập số CP + Giá vốn ở sheet "HỆ THỐNG QUẢN LÝ"
A9: Mã CP | B9: Ngành | C9: Số CP nắm | D9: Giá vốn TB | E9: Giá TT (Auto) | F9: GT hiện tại | G9: Lãi/Lỗ (đ) | H9: % L/L | I9: ROE | J9: P/E | K9: Tỷ trọng thực tế | L9: Tỷ trọng mục tiêu | M9: Chênh lệch | N9: Tín hiệu AI | O9: Điểm TH | P9: Xếp hạng | Q9: Cổ tức /CP | R9: Hành động | S9: VaR 1 ngày | T9: 🚦 Status
A10: FPT | C10: 200 | D10: 62500 | E10: 71900 | F10: 14380000 | G10: 1880000 | H10: 0.1504 | I10: 0.242 | J10: 16 | K10: 0.1445 | L10: 0.125 | M10: 0.0195 | N10: 🟢 MUA | O10: 90 | P10: ⭐ | Q10: 450000 | R10: Giữ nguyên | S10: -1294 | T10: 🟢 OK
A11: MBB | C11: 500 | D11: 22000 | E11: 26150 | F11: 13075000 | G11: 2075000 | H11: 0.1886 | I11: 0.221 | J11: 6.4 | K11: 0.1314 | L11: 0.125 | M11: 0.0064 | N11: 🟢 MUA | O11: 110 | P11: ⭐ | Q11: 550000 | R11: Giữ nguyên | S11: -549 | T11: 🟢 OK
A12: VCB | C12: 100 | D12: 55000 | E12: 60700 | F12: 6070000 | G12: 570000 | H12: 0.1036 | I12: 0.175 | J12: 14 | K12: 0.061 | L12: 0.125 | M12: -0.064 | N12: 🟡 GIỮ | O12: 72 | P12: A | Q12: 110000 | R12: Tích lũy thêm | S12: -850 | T12: 🟢 OK
A13: CTR | C13: 120 | D13: 68000 | E13: 83400 | F13: 10008000 | G13: 1848000 | H13: 0.2265 | I13: 0.228 | J13: 22.5 | K13: 0.1006 | L13: 0.125 | M13: -0.0244 | N13: 🟢 MUA | O13: 79 | P13: A | Q13: 240000 | R13: Giữ nguyên | S13: -1835 | T13: 🟢 OK
A14: MWG | C14: 100 | D14: 75000 | E14: 84600 | F14: 8460000 | G14: 960000 | H14: 0.128 | I14: 0.22 | J14: 17.7 | K14: 0.085 | L14: 0.125 | M14: -0.04 | N14: 🟢 MUA | O14: 80 | P14: ⭐ | Q14: 0 | R14: Tích lũy thêm | S14: -2115 | T14: 🟢 OK
A15: HPG | C15: 600 | D15: 24000 | E15: 27850 | F15: 16710000 | G15: 2310000 | H15: 0.1604 | I15: 0.138 | J15: 13.7 | K15: 0.168 | L15: 0.125 | M15: 0.043 | N15: 🟡 GIỮ | O15: 64 | P15: B | Q15: 0 | R15: Giữ nguyên | S15: -780 | T15: 🟢 OK
A16: VNM | C16: 200 | D16: 58000 | E16: 60900 | F16: 12180000 | G16: 580000 | H16: 0.05 | I16: 0.275 | J16: 14.7 | K16: 0.1224 | L16: 0.125 | M16: -0.0026 | N16: 🟢 MUA | O16: 95 | P16: ⭐ | Q16: 670000 | R16: Giữ nguyên | S16: -731 | T16: 🟡 Watch
A17: VIX | C17: 1000 | D17: 14500 | E17: 18600 | F17: 18600000 | G17: 4100000 | H17: 0.2828 | I17: 0.145 | J17: 12 | K17: 0.187 | L17: 0.125 | M17: 0.062 | N17: 🟡 GIỮ | O17: 64 | P17: B | Q17: 0 | R17: Gọt tỉa | S17: -651 | T17: 🟢 OK
A18: TỔNG CỘNG | F18: 99483000 | G18: 14323000 | H18: 0.1682 | Q18: 2020000
A35: 📐 PHÂN TÍCH DANH MỤC THEO P/E TRUNG BÌNH
A36: P/E TB Danh mục | C36: So sánh VN-Index P/E hiện tại ~12-15x
A37: ROE TB Danh mục | C37: Benchmark ROE trung bình thị trường ~14%
A38: Số mã MUA MẠNH | C38: Cơ hội hiện tại
A39: Số mã cần THOÁT | C39: Kiểm tra danh mục

Sheet 📓 NHẬT KÝ GIAO DỊCH v20
A1: 📓 NHẬT KÝ GIAO DỊCH — Ghi lệnh MUA/BÁN + Lý do + Kết quả | Tự tính P&L
A2: ?? NHAP VAO: Ngay ? Ma ? Loai ? Gia ? So CP ? Ly do ? Ket qua | Q2 2026 | BCTC Q1/2026
A3: 📊 Tổng GD | C3: ✅ Lệnh MUA | E3: ❌ Lệnh BÁN | G3: 💰 Tổng P&L | I3: 🏆 Lệnh Thắng | K3: 📉 Lệnh Thua | M3: 🎯 Win Rate | O3: 💸 P&L TB/GD
A5: 📅 Ngày GD | B5: Mã CP | C5: Tên CT | D5: Loại (MUA/BÁN) | E5: Giá Thực hiện | F5: Số CP | G5: Tổng GT (đ) | H5: Phí GD (0.15%) | I5: Thuế Bán (0.1%) | J5: Giá vốn TB trước | K5: Giá vốn TB sau | L5: 🟢 P&L (đ) | M5: % L/L vị thế | N5: Lý do Giao dịch | O5: Kết quả thực tế | P5: Bài học / Ghi chú
A6: 15/01/2026 | B6: FPT | C6: FPT Corp | D6: MUA | E6: 62500 | F6: 200 | G6: 12500000 | H6: 18750 | I6: =IF(AND(D6="BÁN",G6<>""),G6*0.001,0) | K6: =IF(D6="MUA",IFERROR((J6*F6+E6*F6)/(F6*2),E6),J6) | L6: =IF(AND(D6="BÁN",E6<>"",F6<>"",J6<>""),ROUND((E6-J6)*F6-H6-I6,0),"") | M6: =IF(AND(L6<>"",J6>0),L6/(J6*F6),"") | N6: M? d?u tich s?n d?i h?n - FPT d?t m?c P/E h?p d?n 12.5 | O6: ? L?i 14% sau 4 th�ng | P6: Dung DCA d?u dan, kh�ng FOMO
A7: 20/01/2026 | B7: MBB | C7: MB Bank | D7: MUA | E7: 22000 | F7: 500 | G7: 11000000 | H7: 16500 | I7: =IF(AND(D7="BÁN",G7<>""),G7*0.001,0) | K7: =IF(D7="MUA",IFERROR((J7*F7+E7*F7)/(F7*2),E7),J7) | L7: =IF(AND(D7="BÁN",E7<>"",F7<>"",J7<>""),ROUND((E7-J7)*F7-H7-I7,0),"") | M7: =IF(AND(L7<>"",J7>0),L7/(J7*F7),"") | N7: P/E 6.4 - r? nh?t ng�nh NH, ROE 22%, c? t?c 5% | O7: ? L?i 13.6% | P7: NH qu?n tr? r?i ro t?t, EPS tang tru?ng d?u
A8: 25/01/2026 | B8: VCB | C8: Vietcombank | D8: MUA | E8: 55000 | F8: 100 | G8: 5500000 | H8: 8250 | I8: =IF(AND(D8="BÁN",G8<>""),G8*0.001,0) | K8: =IF(D8="MUA",IFERROR((J8*F8+E8*F8)/(F8*2),E8),J8) | L8: =IF(AND(D8="BÁN",E8<>"",F8<>"",J8<>""),ROUND((E8-J8)*F8-H8-I8,0),"") | M8: =IF(AND(L8<>"",J8>0),L8/(J8*F8),"") | N8: NH l?n nh?t VN - d?t m?c P/B 2.4 h?p d?n | O8: ? L?i 14.2% | P8: Ng�n h�ng s? 1 v? qu?n tr? r?i ro
A9: 46144 | B9: CTR | C9: Viettel Construction | D9: MUA | E9: 68000 | F9: 120 | G9: 8160000 | H9: 12240 | I9: =IF(AND(D9="BÁN",G9<>""),G9*0.001,0) | K9: =IF(D9="MUA",IFERROR((J9*F9+E9*F9)/(F9*2),E9),J9) | L9: =IF(AND(D9="BÁN",E9<>"",F9<>"",J9<>""),ROUND((E9-J9)*F9-H9-I9,0),"") | M9: =IF(AND(L9<>"",J9>0),L9/(J9*F9),"") | N9: 5G Viettel + h? t?ng s? - tang tru?ng 22% EPS | O9: ? L?i 32.4% | P9: CTR hu?ng l?i đ?u tu c�ng d?ch v? 5G&4G
A10: 15/02/2026 | B10: MWG | C10: Mobile World | D10: MUA | E10: 75000 | F10: 100 | G10: 7500000 | H10: 11250 | I10: =IF(AND(D10="BÁN",G10<>""),G10*0.001,0) | K10: =IF(D10="MUA",IFERROR((J10*F10+E10*F10)/(F10*2),E10),J10) | L10: =IF(AND(D10="BÁN",E10<>"",F10<>"",J10<>""),ROUND((E10-J10)*F10-H10-I10,0),"") | M10: =IF(AND(L10<>"",J10>0),L10/(J10*F10),"") | N10: BHX b?t d?u c� l�i - chu k? ph?c h?i ti�u d�ng | O10: ? L?i 3.6% | P10: D?nh gi� c�n h?p d?n khi BHX h�a v?n
A11: 46025 | B11: HPG | C11: H�a Ph�t | D11: MUA | E11: 24000 | F11: 600 | G11: 14400000 | H11: 21600 | I11: =IF(AND(D11="BÁN",G11<>""),G11*0.001,0) | K11: =IF(D11="MUA",IFERROR((J11*F11+E11*F11)/(F11*2),E11),J11) | L11: =IF(AND(D11="BÁN",E11<>"",F11<>"",J11<>""),ROUND((E11-J11)*F11-H11-I11,0),"") | M11: =IF(AND(L11<>"",J11>0),L11/(J11*F11),"") | N11: Chu k? th�p ph?c h?i - Dung Qu?t 2 ch?y full c�ng su?t | O11: ? L?i 0% - dang gi� v?n | P11: HPG chu k? - c?n ki�n nh?n ch? gi� th�p ph?c h?i
A12: 45726 | B12: VNM | C12: Vinamilk | D12: MUA | E12: 58000 | F12: 200 | G12: 11600000 | H12: 17400 | I12: =IF(AND(D12="BÁN",G12<>""),G12*0.001,0) | K12: =IF(D12="MUA",IFERROR((J12*F12+E12*F12)/(F12*2),E12),J12) | L12: =IF(AND(D12="BÁN",E12<>"",F12<>"",J12<>""),ROUND((E12-J12)*F12-H12-I12,0),"") | M12: =IF(AND(L12<>"",J12>0),L12/(J12*F12),"") | N12: C? t?c 7.14% - ph�ng th? danh m?c - P/E 15.2 h?p d?n | O12: ? L?i 1.7% + c? t?c | P12: VNM la m� kho� b?o to�n v?n t?t cho danh m?c
A13: 20/03/2026 | B13: VIX | C13: VIX Securities | D13: MUA | E13: 14500 | F13: 1000 | G13: 14500000 | H13: 21750 | I13: =IF(AND(D13="BÁN",G13<>""),G13*0.001,0) | K13: =IF(D13="MUA",IFERROR((J13*F13+E13*F13)/(F13*2),E13),J13) | L13: =IF(AND(D13="BÁN",E13<>"",F13<>"",J13<>""),ROUND((E13-J13)*F13-H13-I13,0),"") | M13: =IF(AND(L13<>"",J13>0),L13/(J13*F13),"") | N13: ROE 29% xu?t s?c, P/E 6.0 r? - CK hu?ng l?i TT tang | O13: ? L?i 21.4% | P13: VIX tang tru?ng nhanh, c?n ch?t l?i m?t ph?n khi d?t 100%
A14: 46146 | B14: DGC | C14: D?c Giang Chem | D14: MUA | E14: 82000 | F14: 100 | G14: 8200000 | H14: 12300 | I14: =IF(AND(D14="BÁN",G14<>""),G14*0.001,0) | K14: =IF(D14="MUA",IFERROR((J14*F14+E14*F14)/(F14*2),E14),J14) | L14: =IF(AND(D14="BÁN",E14<>"",F14<>"",J14<>""),ROUND((E14-J14)*F14-H14-I14,0),"") | M14: =IF(AND(L14<>"",J14>0),L14/(J14*F14),"") | N14: P 3-5 nam nh? Pho - ROE 28.5%, moat h�a ch?t | O14: ? L?i 3.7% | P14: DGC h��ng l?i t? gia c�ng xu?t kh?u ph�n b�n
A15: 15/05/2026 | B15: VIX | C15: VIX Securities | D15: BAN | E15: 18600 | F15: 300 | G15: 5580000 | H15: 8370 | I15: 5580 | K15: =IF(D15="MUA",IFERROR((J15*F15+E15*F15)/(F15*2),E15),J15) | L15: =IF(AND(D15="BÁN",E15<>"",F15<>"",J15<>""),ROUND((E15-J15)*F15-H15-I15,0),"") | M15: =IF(AND(L15<>"",J15>0),L15/(J15*F15),"") | N15: Ch?t l?i 30% v? th? VIX - ROI 28.3% sau 2 th�ng | O15: ? L?i 28.3% - ch?t l?i th�nh c�ng | P15: Lu�n ch?t 30% khi m?t CP x2, s? c�n 70% ch?y ti?p
A16: 20/05/2026 | B16: MBB | C16: MB Bank | D16: MUA | E16: 24000 | F16: 200 | G16: 4800000 | H16: 7200 | I16: =IF(AND(D16="BÁN",G16<>""),G16*0.001,0) | K16: =IF(D16="MUA",IFERROR((J16*F16+E16*F16)/(F16*2),E16),J16) | L16: =IF(AND(D16="BÁN",E16<>"",F16<>"",J16<>""),ROUND((E16-J16)*F16-H16-I16,0),"") | M16: =IF(AND(L16<>"",J16>0),L16/(J16*F16),"") | N16: DCA MBB khi gi� di?u ch?nh v? 24K - P/E 6, ROE 22% | O16: ? M?i mua 1 tu?n | P16: DCA khi gi?m 5%+ t? gi� v?n TB
C17: =IFERROR(VLOOKUP(B17,'📈 Cổ Phiếu VN 🔍'!$A:$C,2,0),"") | G17: =IF(AND(E17<>"",F17<>""),E17*F17,"") | H17: =IF(G17<>"",G17*0.0015,"") | I17: =IF(AND(D17="BÁN",G17<>""),G17*0.001,0) | K17: =IF(D17="MUA",IFERROR((J17*F17+E17*F17)/(F17*2),E17),J17) | L17: =IF(AND(D17="BÁN",E17<>"",F17<>"",J17<>""),ROUND((E17-J17)*F17-H17-I17,0),"") | M17: =IF(AND(L17<>"",J17>0),L17/(J17*F17),"")
C18: =IFERROR(VLOOKUP(B18,'📈 Cổ Phiếu VN 🔍'!$A:$C,2,0),"") | G18: =IF(AND(E18<>"",F18<>""),E18*F18,"") | H18: =IF(G18<>"",G18*0.0015,"") | I18: =IF(AND(D18="BÁN",G18<>""),G18*0.001,0) | K18: =IF(D18="MUA",IFERROR((J18*F18+E18*F18)/(F18*2),E18),J18) | L18: =IF(AND(D18="BÁN",E18<>"",F18<>"",J18<>""),ROUND((E18-J18)*F18-H18-I18,0),"") | M18: =IF(AND(L18<>"",J18>0),L18/(J18*F18),"")
A19: 28/05/2026 | B19: HPG | C19: Hoa Phat | D19: MUA | E19: 26500 | F19: 400 | G19: 10600000 | H19: 15900 | I19: =IF(AND(D19="BÁN",G19<>""),G19*0.001,0) | K19: 5300000 | L19: =IF(AND(D19="BÁN",E19<>"",F19<>"",J19<>""),ROUND((E19-J19)*F19-H19-I19,0),"") | M19: =IF(AND(L19<>"",J19>0),L19/(J19*F19),"") | N19: DCA HPG - Q2 steel demand tang + Dung Quat 2 full CS
A20: 29/05/2026 | B20: FPT | C20: FPT Corp | D20: MUA | E20: 71200 | F20: 50 | G20: 3560000 | H20: 5340 | I20: =IF(AND(D20="BÁN",G20<>""),G20*0.001,0) | K20: 1780000 | L20: =IF(AND(D20="BÁN",E20<>"",F20<>"",J20<>""),ROUND((E20-J20)*F20-H20-I20,0),"") | M20: =IF(AND(L20<>"",J20>0),L20/(J20*F20),"") | N20: DCA FPT - P/E 20.3 con hap dan, dat trong nuoc + quoc te tang
C21: =IFERROR(VLOOKUP(B21,'📈 Cổ Phiếu VN 🔍'!$A:$C,2,0),"") | G21: =IF(AND(E21<>"",F21<>""),E21*F21,"") | H21: =IF(G21<>"",G21*0.0015,"") | I21: =IF(AND(D21="BÁN",G21<>""),G21*0.001,0) | K21: =IF(D21="MUA",IFERROR((J21*F21+E21*F21)/(F21*2),E21),J21) | L21: =IF(AND(D21="BÁN",E21<>"",F21<>"",J21<>""),ROUND((E21-J21)*F21-H21-I21,0),"") | M21: =IF(AND(L21<>"",J21>0),L21/(J21*F21),"")
C22: =IFERROR(VLOOKUP(B22,'📈 Cổ Phiếu VN 🔍'!$A:$C,2,0),"") | G22: =IF(AND(E22<>"",F22<>""),E22*F22,"") | H22: =IF(G22<>"",G22*0.0015,"") | I22: =IF(AND(D22="BÁN",G22<>""),G22*0.001,0) | K22: =IF(D22="MUA",IFERROR((J22*F22+E22*F22)/(F22*2),E22),J22) | L22: =IF(AND(D22="BÁN",E22<>"",F22<>"",J22<>""),ROUND((E22-J22)*F22-H22-I22,0),"") | M22: =IF(AND(L22<>"",J22>0),L22/(J22*F22),"")
C23: =IFERROR(VLOOKUP(B23,'📈 Cổ Phiếu VN 🔍'!$A:$C,2,0),"") | G23: =IF(AND(E23<>"",F23<>""),E23*F23,"") | H23: =IF(G23<>"",G23*0.0015,"") | I23: =IF(AND(D23="BÁN",G23<>""),G23*0.001,0) | K23: =IF(D23="MUA",IFERROR((J23*F23+E23*F23)/(F23*2),E23),J23) | L23: =IF(AND(D23="BÁN",E23<>"",F23<>"",J23<>""),ROUND((E23-J23)*F23-H23-I23,0),"") | M23: =IF(AND(L23<>"",J23>0),L23/(J23*F23),"")
C24: =IFERROR(VLOOKUP(B24,'📈 Cổ Phiếu VN 🔍'!$A:$C,2,0),"") | G24: =IF(AND(E24<>"",F24<>""),E24*F24,"") | H24: =IF(G24<>"",G24*0.0015,"") | I24: =IF(AND(D24="BÁN",G24<>""),G24*0.001,0) | K24: =IF(D24="MUA",IFERROR((J24*F24+E24*F24)/(F24*2),E24),J24) | L24: =IF(AND(D24="BÁN",E24<>"",F24<>"",J24<>""),ROUND((E24-J24)*F24-H24-I24,0),"") | M24: =IF(AND(L24<>"",J24>0),L24/(J24*F24),"")
